Workbook

Sheet Petunjuk
B2: PANDUAN PENGGUNAAN — Template Penilaian MK & Evaluasi Ketercapaian CPMK
B3: Template generik — berlaku untuk mata kuliah apa pun. Ganti [Nama Mata Kuliah] di setiap judul sheet.
B5: Sheet "Bobot CPMK"
B6: Diisi SEKALI di awal semester (idealnya sesuai RPS). Kolom instrumen (E s.d. M) mengikuti 9 komponen skema nilai resmi Politeknik WBI — Quiz (QUI), Tugas (TTS), UTS, UAS, Unjuk Kinerja (UKN), Proyek (PRY), Portofolio (POR), Produk (PRD), Presentasi (PRE) — plus kolom Sikap (N) yang dinilai holistik satu kali per mahasiswa. Kolom yang tidak dipakai MK Anda boleh dibiarkan 0/kosong. Isi "Bobot thd MK (%)" (kolom O, otomatis dari SUM instrumen) dan "Bobot thd CPMK (%)" (kolom P, porsi Sub-CPMK ini di antara sesama anggota CPMK-nya — harus 100% per kelompok CPMK; kolom Q & R mengecek ini otomatis, tidak perlu mengetik nama CPMK satu-satu di rumus). Sel abu-abu muda boleh diisi/disesuaikan; jangan mengubah struktur/urutan baris karena sheet lain merujuk ke posisi baris ini.
B8: Sheet "Peta CPL"
B9: Diisi/disesuaikan SEKALI di awal semester. Tabel 1: daftar CPL yang dibebankan pada MK ini beserta rumusannya. Tabel 2: pemetaan CPMK ke CPL berupa matriks — kolom "Bobot thd MK (%)" terisi OTOMATIS (dijumlahkan dari sheet Bobot CPMK berdasarkan kode CPMK yang Anda ketik di kolom A). Isi 1 pada kolom kode CPL yang bersangkutan jika CPMK itu berkontribusi ke CPL tsb (satu CPMK boleh berkontribusi ke lebih dari satu CPL), kosongkan jika tidak. Dari peta inilah nilai CPL per mahasiswa dihitung otomatis.
B11: Sheet "Input Nilai"
B12: SATU-SATUNYA sheet yang perlu diisi dosen rutin per mahasiswa. Cukup isi kolom NIM, Nama, dan nilai (0-100) di sel abu-abu muda sesuai instrumen & Sub-CPMK-nya, termasuk nilai Sikap (kolom terakhir sebelum hasil). Nilai Sikap cukup diisi SATU KALI per mahasiswa (berlaku untuk semua Sub-CPMK/CPMK). Baris kosong boleh dihapus/diisi; untuk menambah mahasiswa di luar 30 baris yang disediakan, salin (copy-paste) satu baris kosong paling bawah ke bawahnya agar formula ikut tersalin.
B14: Sheet "Nilai CPMK per Mahasiswa"
B15: Terisi OTOMATIS. Menampilkan nilai tiap Sub-CPMK, nilai tiap CPMK, nilai tiap CPL (hasil pemetaan di sheet "Peta CPL"), dan Nilai Akhir MK untuk setiap mahasiswa berdasarkan input di sheet "Input Nilai". Tidak perlu diisi manual. Kolom CPMK/CPL yang tidak Anda pakai (Peta CPL dibiarkan kosong) akan tampil kosong secara wajar.
B17: Sheet "Evaluasi Ketercapaian CPMK"
B18: Terisi OTOMATIS. Dashboard tingkat kelas dengan 4 bagian: (A) Sub-CPMK, (B) CPMK, (C) CPL, dan (D) ringkasan kelulusan MK — masing-masing menampilkan rata-rata, nilai tertinggi/terendah, jumlah & persentase mahasiswa yang mencapai ambang batas, serta status "Tercapai / Belum Tercapai". Tiga parameter (di sheet Bobot CPMK, baris 17-19) bisa diubah sesuai kebijakan prodi/SPMI: Nilai Batas Lulus MK, Batas Nilai 'Tercapai' per mahasiswa, dan Batas % Kelas agar CPMK dianggap tercapai.
... B24: • Sheet ini menyediakan 8 baris Sub-CPMK, 8 baris CPMK unik, dan 6 kode CPL sebagai kapasitas maksimum — biarkan baris yang tidak dipakai kosong; jangan menghapus baris/kolom karena akan merusak rujukan rumus antar sheet. Bila MK Anda butuh lebih dari batas ini, salin pola kolom/baris yang sudah ada dan sesuaikan rentang rumusnya secara konsisten.

Sheet Bobot CPMK
A1: BOBOT PENILAIAN PER SUB-CPMK — [Nama Mata Kuliah]
A2: Sel abu-abu muda = boleh diisi/disesuaikan. Jangan ubah urutan/posisi baris Sub-CPMK. Kolom instrumen (E s.d. M) + Sikap (N) mengikuti 9+1 komponen skema nilai resmi Politeknik WBI — kolom yang tidak dipakai MK ini boleh dibiarkan kosong/0.
A3: No | B3: CPMK | C3: Sub-CPMK | D3: Bahan Kajian / Kemampuan Akhir | E3: QUI (%) | F3: TTS (%) | G3: UTS (%) | H3: UAS (%) | I3: UKN (%) | J3: PRY (%) | K3: POR (%) | L3: PRD (%) | M3: PRE (%) | N3: Sikap (%) | O3: Bobot thd MK (%) | P3: Bobot thd CPMK (%) | Q3: Cek Bobot thd CPMK | R3: Status
A4: 1 | E4: 0 | F4: 0 | G4: 0 | H4: 0 | I4: 0 | J4: 0 | K4: 0 | L4: 0 | M4: 0 | N4: 0 | O4: =SUM(E4:N4) | P4: 0 | Q4: =IF(B4="","",SUMIF($B$4:$B$11,B4,$P$4:$P$11)) | R4: =IF(Q4="","",IF(Q4=100,"OK","!! PERIKSA"))
A5: 2 | E5: 0 | F5: 0 | G5: 0 | H5: 0 | I5: 0 | J5: 0 | K5: 0 | L5: 0 | M5: 0 | N5: 0 | O5: =SUM(E5:N5) | P5: 0 | Q5: =IF(B5="","",SUMIF($B$4:$B$11,B5,$P$4:$P$11)) | R5: =IF(Q5="","",IF(Q5=100,"OK","!! PERIKSA"))
A6: 3 | E6: 0 | F6: 0 | G6: 0 | H6: 0 | I6: 0 | J6: 0 | K6: 0 | L6: 0 | M6: 0 | N6: 0 | O6: =SUM(E6:N6) | P6: 0 | Q6: =IF(B6="","",SUMIF($B$4:$B$11,B6,$P$4:$P$11)) | R6: =IF(Q6="","",IF(Q6=100,"OK","!! PERIKSA"))
A7: 4 | E7: 0 | F7: 0 | G7: 0 | H7: 0 | I7: 0 | J7: 0 | K7: 0 | L7: 0 | M7: 0 | N7: 0 | O7: =SUM(E7:N7) | P7: 0 | Q7: =IF(B7="","",SUMIF($B$4:$B$11,B7,$P$4:$P$11)) | R7: =IF(Q7="","",IF(Q7=100,"OK","!! PERIKSA"))
A8: 5 | E8: 0 | F8: 0 | G8: 0 | H8: 0 | I8: 0 | J8: 0 | K8: 0 | L8: 0 | M8: 0 | N8: 0 | O8: =SUM(E8:N8) | P8: 0 | Q8: =IF(B8="","",SUMIF($B$4:$B$11,B8,$P$4:$P$11)) | R8: =IF(Q8="","",IF(Q8=100,"OK","!! PERIKSA"))
A9: 6 | E9: 0 | F9: 0 | G9: 0 | H9: 0 | I9: 0 | J9: 0 | K9: 0 | L9: 0 | M9: 0 | N9: 0 | O9: =SUM(E9:N9) | P9: 0 | Q9: =IF(B9="","",SUMIF($B$4:$B$11,B9,$P$4:$P$11)) | R9: =IF(Q9="","",IF(Q9=100,"OK","!! PERIKSA"))
A10: 7 | E10: 0 | F10: 0 | G10: 0 | H10: 0 | I10: 0 | J10: 0 | K10: 0 | L10: 0 | M10: 0 | N10: 0 | O10: =SUM(E10:N10) | P10: 0 | Q10: =IF(B10="","",SUMIF($B$4:$B$11,B10,$P$4:$P$11)) | R10: =IF(Q10="","",IF(Q10=100,"OK","!! PERIKSA"))
A11: 8 | E11: 0 | F11: 0 | G11: 0 | H11: 0 | I11: 0 | J11: 0 | K11: 0 | L11: 0 | M11: 0 | N11: 0 | O11: =SUM(E11:N11) | P11: 0 | Q11: =IF(B11="","",SUMIF($B$4:$B$11,B11,$P$4:$P$11)) | R11: =IF(Q11="","",IF(Q11=100,"OK","!! PERIKSA"))
D12: TOTAL BOBOT | E12: =SUM(E4:E11) | F12: =SUM(F4:F11) | G12: =SUM(G4:G11) | H12: =SUM(H4:H11) | I12: =SUM(I4:I11) | J12: =SUM(J4:J11) | K12: =SUM(K4:K11) | L12: =SUM(L4:L11) | ... O12: =SUM(O4:O11)
D13: Cek total bobot thd MK harus = 100%: | O13: =IF(O12=100,"OK 100%","!! PERIKSA: "&O12&"%")
B15: PARAMETER PENILAIAN (boleh disesuaikan dengan pedoman akademik institusi/SPMI)
B16: Skala Nilai Huruf
B17: Batas Bawah | C17: Huruf | D17: Bobot | R17: Nilai Batas Lulus MK
B18: 0 | C18: E | D18: 0
B19: 50 | C19: D | D19: 1 | R19: Batas Nilai 'Tercapai' per Mhs (Sub-CPMK/CPMK)
B20: 60 | C20: C | D20: 2 | R20: Batas % Kelas agar CPMK Dianggap Tercapai
B21: 70 | C21: B | D21: 3
B22: 80 | C22: A | D22: 4

Sheet Peta CPL
A1: PETA CPL & PEMETAAN CPMK — [Nama Mata Kuliah]
A2: Nilai CPL di sini adalah KONTRIBUSI mata kuliah ini saja, bukan capaian CPL final (CPL dicapai lintas beberapa mata kuliah dalam kurikulum — lihat catatan di sheet Petunjuk).
A3: 1. CPL yang Dibebankan pada Mata Kuliah
A4: Kode | B4: Rumusan CPL yang Dibebankan
A12: 2. Pemetaan CPMK ke CPL — isi 1 jika CPMK berkontribusi ke CPL tsb, kosongkan jika tidak
A13: CPMK | B13: Rumusan CPMK | C13: Bobot thd MK (%) | D13: =A5 | E13: =A6 | F13: =A7 | G13: =A8 | H13: =A9 | I13: =A10
C14: =IF(A14="","",SUMIF('Bobot CPMK'!$B$4:$B$11,A14,'Bobot CPMK'!$O$4:$O$11))
C15: =IF(A15="","",SUMIF('Bobot CPMK'!$B$4:$B$11,A15,'Bobot CPMK'!$O$4:$O$11))
C16: =IF(A16="","",SUMIF('Bobot CPMK'!$B$4:$B$11,A16,'Bobot CPMK'!$O$4:$O$11))
C17: =IF(A17="","",SUMIF('Bobot CPMK'!$B$4:$B$11,A17,'Bobot CPMK'!$O$4:$O$11))
C18: =IF(A18="","",SUMIF('Bobot CPMK'!$B$4:$B$11,A18,'Bobot CPMK'!$O$4:$O$11))
C19: =IF(A19="","",SUMIF('Bobot CPMK'!$B$4:$B$11,A19,'Bobot CPMK'!$O$4:$O$11))
C20: =IF(A20="","",SUMIF('Bobot CPMK'!$B$4:$B$11,A20,'Bobot CPMK'!$O$4:$O$11))
C21: =IF(A21="","",SUMIF('Bobot CPMK'!$B$4:$B$11,A21,'Bobot CPMK'!$O$4:$O$11))

Sheet Input Nilai
A1: INPUT NILAI MAHASISWA — [Nama Mata Kuliah]
A2: Isi hanya sel abu-abu muda (skor 0-100). Nilai Sikap cukup diisi SATU KALI per mahasiswa (dinilai holistik, mis. di akhir semester). Nilai per Sub-CPMK, per CPMK, per CPL, dan Nilai Akhir MK terisi otomatis di sheet lain.
A3: No | B3: NIM | C3: Nama Mahasiswa | D3: Sub-CPMK 1 | M3: Sub-CPMK 2 | V3: Sub-CPMK 3 | AE3: Sub-CPMK 4 | AN3: Sub-CPMK 5 | AW3: Sub-CPMK 6 | BF3: Sub-CPMK 7 | BO3: Sub-CPMK 8 | BX3: Sikap (1x/mhs) | BY3: Nilai Akhir MK | BZ3: Nilai Huruf | CA3: Keterangan
D4: QUI | E4: TTS | F4: UTS | G4: UAS | H4: UKN | I4: PRY | J4: POR | K4: PRD | L4: PRE | M4: QUI | N4: TTS | O4: UTS | P4: UAS | Q4: UKN | R4: PRY | S4: POR | T4: PRD | U4: PRE | V4: QUI | W4: TTS | X4: UTS | Y4: UAS | Z4: UKN | AA4: PRY | AB4: POR | AC4: PRD | AD4: PRE | AE4: QUI | AF4: TTS | AG4: UTS | AH4: UAS | AI4: UKN | AJ4: PRY | AK4: POR | AL4: PRD | AM4: PRE | AN4: QUI | AO4: TTS | AP4: UTS | AQ4: UAS | AR4: UKN | AS4: PRY | AT4: POR | AU4: PRD | AV4: PRE | AW4: QUI | AX4: TTS | AY4: UTS | AZ4: UAS | BA4: UKN | BB4: PRY | BC4: POR | BD4: PRD | BE4: PRE | BF4: QUI | BG4: TTS | BH4: UTS | BI4: UAS | BJ4: UKN | BK4: PRY | BL4: POR | BM4: PRD | BN4: PRE | BO4: QUI | BP4: TTS | BQ4: UTS | BR4: UAS | BS4: UKN | BT4: PRY | BU4: POR | BV4: PRD | BW4: PRE
A5: 1 | BY5: =IF($B5="","",'Nilai CPMK per Mahasiswa'!Z5) | BZ5: =IF(BY5="","",VLOOKUP(BY5,'Bobot CPMK'!$B$17:$D$21,2,TRUE())) | CA5: =IF(BY5="","",IF(BY5>='Bobot CPMK'!$T$17,"Lulus","Tidak Lulus"))
A6: 2 | BY6: =IF($B6="","",'Nilai CPMK per Mahasiswa'!Z6) | BZ6: =IF(BY6="","",VLOOKUP(BY6,'Bobot CPMK'!$B$17:$D$21,2,TRUE())) | CA6: =IF(BY6="","",IF(BY6>='Bobot CPMK'!$T$17,"Lulus","Tidak Lulus"))
A7: 3 | BY7: =IF($B7="","",'Nilai CPMK per Mahasiswa'!Z7) | BZ7: =IF(BY7="","",VLOOKUP(BY7,'Bobot CPMK'!$B$17:$D$21,2,TRUE())) | CA7: =IF(BY7="","",IF(BY7>='Bobot CPMK'!$T$17,"Lulus","Tidak Lulus"))
A8: 4 | BY8: =IF($B8="","",'Nilai CPMK per Mahasiswa'!Z8) | BZ8: =IF(BY8="","",VLOOKUP(BY8,'Bobot CPMK'!$B$17:$D$21,2,TRUE())) | CA8: =IF(BY8="","",IF(BY8>='Bobot CPMK'!$T$17,"Lulus","Tidak Lulus"))
A9: 5 | BY9: =IF($B9="","",'Nilai CPMK per Mahasiswa'!Z9) | BZ9: =IF(BY9="","",VLOOKUP(BY9,'Bobot CPMK'!$B$17:$D$21,2,TRUE())) | CA9: =IF(BY9="","",IF(BY9>='Bobot CPMK'!$T$17,"Lulus","Tidak Lulus"))
A10: 6 | BY10: =IF($B10="","",'Nilai CPMK per Mahasiswa'!Z10) | BZ10: =IF(BY10="","",VLOOKUP(BY10,'Bobot CPMK'!$B$17:$D$21,2,TRUE())) | CA10: =IF(BY10="","",IF(BY10>='Bobot CPMK'!$T$17,"Lulus","Tidak Lulus"))
A11: 7 | BY11: =IF($B11="","",'Nilai CPMK per Mahasiswa'!Z11) | BZ11: =IF(BY11="","",VLOOKUP(BY11,'Bobot CPMK'!$B$17:$D$21,2,TRUE())) | CA11: =IF(BY11="","",IF(BY11>='Bobot CPMK'!$T$17,"Lulus","Tidak Lulus"))
A12: 8 | BY12: =IF($B12="","",'Nilai CPMK per Mahasiswa'!Z12) | BZ12: =IF(BY12="","",VLOOKUP(BY12,'Bobot CPMK'!$B$17:$D$21,2,TRUE())) | CA12: =IF(BY12="","",IF(BY12>='Bobot CPMK'!$T$17,"Lulus","Tidak Lulus"))
A13: 9 | BY13: =IF($B13="","",'Nilai CPMK per Mahasiswa'!Z13) | BZ13: =IF(BY13="","",VLOOKUP(BY13,'Bobot CPMK'!$B$17:$D$21,2,TRUE())) | CA13: =IF(BY13="","",IF(BY13>='Bobot CPMK'!$T$17,"Lulus","Tidak Lulus"))
A14: 10 | BY14: =IF($B14="","",'Nilai CPMK per Mahasiswa'!Z14) | BZ14: =IF(BY14="","",VLOOKUP(BY14,'Bobot CPMK'!$B$17:$D$21,2,TRUE())) | CA14: =IF(BY14="","",IF(BY14>='Bobot CPMK'!$T$17,"Lulus","Tidak Lulus"))
A15: 11 | BY15: =IF($B15="","",'Nilai CPMK per Mahasiswa'!Z15) | BZ15: =IF(BY15="","",VLOOKUP(BY15,'Bobot CPMK'!$B$17:$D$21,2,TRUE())) | CA15: =IF(BY15="","",IF(BY15>='Bobot CPMK'!$T$17,"Lulus","Tidak Lulus"))
A16: 12 | BY16: =IF($B16="","",'Nilai CPMK per Mahasiswa'!Z16) | BZ16: =IF(BY16="","",VLOOKUP(BY16,'Bobot CPMK'!$B$17:$D$21,2,TRUE())) | CA16: =IF(BY16="","",IF(BY16>='Bobot CPMK'!$T$17,"Lulus","Tidak Lulus"))
... A34: 30 | BY34: =IF($B34="","",'Nilai CPMK per Mahasiswa'!Z34) | BZ34: =IF(BY34="","",VLOOKUP(BY34,'Bobot CPMK'!$B$17:$D$21,2,TRUE())) | CA34: =IF(BY34="","",IF(BY34>='Bobot CPMK'!$T$17,"Lulus","Tidak Lulus"))

Sheet Nilai CPMK per Mahasiswa
A1: NILAI CPMK / CPL PER MAHASISWA — [Nama Mata Kuliah]
A2: Terisi OTOMATIS dari sheet "Input Nilai", "Bobot CPMK", dan "Peta CPL". Tidak perlu diisi manual.
A4: No | B4: NIM | C4: Nama Mahasiswa | D4: Sub-CPMK 1 | E4: Sub-CPMK 2 | F4: Sub-CPMK 3 | G4: Sub-CPMK 4 | H4: Sub-CPMK 5 | I4: Sub-CPMK 6 | J4: Sub-CPMK 7 | K4: Sub-CPMK 8 | L4: =IF('Peta CPL'!$A$14="","CPMK-1",'Peta CPL'!$A$14) | M4: =IF('Peta CPL'!$A$15="","CPMK-2",'Peta CPL'!$A$15) | N4: =IF('Peta CPL'!$A$16="","CPMK-3",'Peta CPL'!$A$16) | O4: =IF('Peta CPL'!$A$17="","CPMK-4",'Peta CPL'!$A$17) | P4: =IF('Peta CPL'!$A$18="","CPMK-5",'Peta CPL'!$A$18) | Q4: =IF('Peta CPL'!$A$19="","CPMK-6",'Peta CPL'!$A$19) | R4: =IF('Peta CPL'!$A$20="","CPMK-7",'Peta CPL'!$A$20) | S4: =IF('Peta CPL'!$A$21="","CPMK-8",'Peta CPL'!$A$21) | T4: =IF('Peta CPL'!$A$5="","CPL-1",'Peta CPL'!$A$5) | U4: =IF('Peta CPL'!$A$6="","CPL-2",'Peta CPL'!$A$6) | V4: =IF('Peta CPL'!$A$7="","CPL-3",'Peta CPL'!$A$7) | W4: =IF('Peta CPL'!$A$8="","CPL-4",'Peta CPL'!$A$8) | X4: =IF('Peta CPL'!$A$9="","CPL-5",'Peta CPL'!$A$9) | Y4: =IF('Peta CPL'!$A$10="","CPL-6",'Peta CPL'!$A$10) | Z4: Nilai Akhir MK
A5: ='Input Nilai'!A5 | B5: ='Input Nilai'!B5 | C5: ='Input Nilai'!C5 | D5: =IF(OR('Input Nilai'!$B5="",'Bobot CPMK'!$O$4=0),"",(SUMPRODUCT('Input Nilai'!D5:L5,'Bobot CPMK'!$E$4:$M$4)+'Input Nilai'!$BX5*'Bobot CPMK'!$N$4)/'Bobot CPMK'!$O$4) | E5: =IF(OR('Input Nilai'!$B5="",'Bobot CPMK'!$O$5=0),"",(SUMPRODUCT('Input Nilai'!M5:U5,'Bobot CPMK'!$E$5:$M$5)+'Input Nilai'!$BX5*'Bobot CPMK'!$N$5)/'Bobot CPMK'!$O$5) | F5: =IF(OR('Input Nilai'!$B5="",'Bobot CPMK'!$O$6=0),"",(SUMPRODUCT('Input Nilai'!V5:AD5,'Bobot CPMK'!$E$6:$M$6)+'Input Nilai'!$BX5*'Bobot CPMK'!$N$6)/'Bobot CPMK'!$O$6) | G5: =IF(OR('Input Nilai'!$B5="",'Bobot CPMK'!$O$7=0),"",(SUMPRODUCT('Input Nilai'!AE5:AM5,'Bobot CPMK'!$E$7:$M$7)+'Input Nilai'!$BX5*'Bobot CPMK'!$N$7)/'Bobot CPMK'!$O$7) | H5: =IF(OR('Input Nilai'!$B5="",'Bobot CPMK'!$O$8=0),"",(SUMPRODUCT('Input Nilai'!AN5:AV5,'Bobot CPMK'!$E$8:$M$8)+'Input Nilai'!$BX5*'Bobot CPMK'!$N$8)/'Bobot CPMK'!$O$8) | I5: =IF(OR('Input Nilai'!$B5="",'Bobot CPMK'!$O$9=0),"",(SUMPRODUCT('Input Nilai'!AW5:BE5,'Bobot CPMK'!$E$9:$M$9)+'Input Nilai'!$BX5*'Bobot CPMK'!$N$9)/'Bobot CPMK'!$O$9) | J5: =IF(OR('Input Nilai'!$B5="",'Bobot CPMK'!$O$10=0),"",(SUMPRODUCT('Input Nilai'!BF5:BN5,'Bobot CPMK'!$E$10:$M$10)+'Input Nilai'!$BX5*'Bobot CPMK'!$N$10)/'Bobot CPMK'!$O$10) | K5: =IF(OR('Input Nilai'!$B5="",'Bobot CPMK'!$O$11=0),"",(SUMPRODUCT('Input Nilai'!BO5:BW5,'Bobot CPMK'!$E$11:$M$11)+'Input Nilai'!$BX5*'Bobot CPMK'!$N$11)/'Bobot CPMK'!$O$11) | L5: =IF(OR($B5="",'Peta CPL'!$A$14=""),"",IFERROR(SUM(IF('Bobot CPMK'!$B$4='Peta CPL'!$A$14,N(D5)*'Bobot CPMK'!$P$4,0),IF('Bobot CPMK'!$B$5='Peta CPL'!$A$14,N(E5)*'Bobot CPMK'!$P$5,0),IF('Bobot CPMK'!$B$6='Peta CPL'!$A$14,N(F5)*'Bobot CPMK'!$P$6,0),IF('Bobot CPMK'!$B$7='Peta CPL'!$A$14,N(G5)*'Bobot CPMK'!$P$7,0),IF('Bobot CPMK'!$B$8='Peta CPL'!$A$14,N(H5)*'Bobot CPMK'!$P$8,0),IF('Bobot CPMK'!$B$9='Peta CPL'!$A$14,N(I5)*'Bobot CPMK'!$P$9,0),IF('Bobot CPMK'!$B$10='Peta CPL'!$A$14,N(J5)*'Bobot CPMK'!$P$10,0),IF('Bobot CPMK'!$B$11='Peta CPL'!$A$14,N(K5)*'Bobot CPMK'!$P$11,0))/SUM(IF('Bobot CPMK'!$B$4='Peta CPL'!$A$14,'Bobot CPMK'!$P$4,0),IF('Bobot CPMK'!$B$5='Peta CPL'!$A$14,'Bobot CPMK'!$P$5,0),IF('Bobot CPMK'!$B$6='Peta CPL'!$A$14,'Bobot CPMK'!$P$6,0),IF('Bobot CPMK'!$B$7='Peta CPL'!$A$14,'Bobot CPMK'!$P$7,0),IF('Bobot CPMK'!$B$8='Peta CPL'!$A$14,'Bobot CPMK'!$P$8,0),IF('Bobot CPMK'!$B$9='Peta CPL'!$A$14,'Bobot CPMK'!$P$9,0),IF('Bobot CPMK'!$B$10='Peta CPL'!$A$14,'Bobot CPMK'!$P$10,0),IF('Bobot CPMK'!$B$11='Peta CPL'!$A$14,'Bobot CPMK'!$P$11,0)),"")) | M5: =IF(OR($B5="",'Peta CPL'!$A$15=""),"",IFERROR(SUM(IF('Bobot CPMK'!$B$4='Peta CPL'!$A$15,N(D5)*'Bobot CPMK'!$P$4,0),IF('Bobot CPMK'!$B$5='Peta CPL'!$A$15,N(E5)*'Bobot CPMK'!$P$5,0),IF('Bobot CPMK'!$B$6='Peta CPL'!$A$15,N(F5)*'Bobot CPMK'!$P$6,0),IF('Bobot CPMK'!$B$7='Peta CPL'!$A$15,N(G5)*'Bobot CPMK'!$P$7,0),IF('Bobot CPMK'!$B$8='Peta CPL'!$A$15,N(H5)*'Bobot CPMK'!$P$8,0),IF('Bobot CPMK'!$B$9='Peta CPL'!$A$15,N(I5)*'Bobot CPMK'!$P$9,0),IF('Bobot CPMK'!$B$10='Peta CPL'!$A$15,N(J5)*'Bobot CPMK'!$P$10,0),IF('Bobot CPMK'!$B$11='Peta CPL'!$A$15,N(K5)*'Bobot CPMK'!$P$11,0))/SUM(IF('Bobot CPMK'!$B$4='Peta CPL'!$A$15,'Bobot CPMK'!$P$4,0),IF('Bobot CPMK'!$B$5='Peta CPL'!$A$15,'Bobot CPMK'!$P$5,0),IF('Bobot CPMK'!$B$6='Peta CPL'!$A$15,'Bobot CPMK'!$P$6,0),IF('Bobot CPMK'!$B$7='Peta CPL'!$A$15,'Bobot CPMK'!$P$7,0),IF('Bobot CPMK'!$B$8='Peta CPL'!$A$15,'Bobot CPMK'!$P$8,0),IF('Bobot CPMK'!$B$9='Peta CPL'!$A$15,'Bobot CPMK'!$P$9,0),IF('Bobot CPMK'!$B$10='Peta CPL'!$A$15,'Bobot CPMK'!$P$10,0),IF('Bobot CPMK'!$B$11='Peta CPL'!$A$15,'Bobot CPMK'!$P$11,0)),"")) | N5: =IF(OR($B5="",'Peta CPL'!$A$16=""),"",IFERROR(SUM(IF('Bobot CPMK'!$B$4='Peta CPL'!$A$16,N(D5)*'Bobot CPMK'!$P$4,0),IF('Bobot CPMK'!$B$5='Peta CPL'!$A$16,N(E5)*'Bobot CPMK'!$P$5,0),IF('Bobot CPMK'!$B$6='Peta CPL'!$A$16,N(F5)*'Bobot CPMK'!$P$6,0),IF('Bobot CPMK'!$B$7='Peta CPL'!$A$16,N(G5)*'Bobot CPMK'!$P$7,0),IF('Bobot CPMK'!$B$8='Peta CPL'!$A$16,N(H5)*'Bobot CPMK'!$P$8,0),IF('Bobot CPMK'!$B$9='Peta CPL'!$A$16,N(I5)*'Bobot CPMK'!$P$9,0),IF('Bobot CPMK'!$B$10='Peta CPL'!$A$16,N(J5)*'Bobot CPMK'!$P$10,0),IF('Bobot CPMK'!$B$11='Peta CPL'!$A$16,N(K5)*'Bobot CPMK'!$P$11,0))/SUM(IF('Bobot CPMK'!$B$4='Peta CPL'!$A$16,'Bobot CPMK'!$P$4,0),IF('Bobot CPMK'!$B$5='Peta CPL'!$A$16,'Bobot CPMK'!$P$5,0),IF('Bobot CPMK'!$B$6='Peta CPL'!$A$16,'Bobot CPMK'!$P$6,0),IF('Bobot CPMK'!$B$7='Peta CPL'!$A$16,'Bobot CPMK'!$P$7,0),IF('Bobot CPMK'!$B$8='Peta CPL'!$A$16,'Bobot CPMK'!$P$8,0),IF('Bobot CPMK'!$B$9='Peta CPL'!$A$16,'Bobot CPMK'!$P$9,0),IF('Bobot CPMK'!$B$10='Peta CPL'!$A$16,'Bobot CPMK'!$P$10,0),IF('Bobot CPMK'!$B$11='Peta CPL'!$A$16,'Bobot CPMK'!$P$11,0)),"")) | O5: =IF(OR($B5="",'Peta CPL'!$A$17=""),"",IFERROR(SUM(IF('Bobot CPMK'!$B$4='Peta CPL'!$A$17,N(D5)*'Bobot CPMK'!$P$4,0),IF('Bobot CPMK'!$B$5='Peta CPL'!$A$17,N(E5)*'Bobot CPMK'!$P$5,0),IF('Bobot CPMK'!$B$6='Peta CPL'!$A$17,N(F5)*'Bobot CPMK'!$P$6,0),IF('Bobot CPMK'!$B$7='Peta CPL'!$A$17,N(G5)*'Bobot CPMK'!$P$7,0),IF('Bobot CPMK'!$B$8='Peta CPL'!$A$17,N(H5)*'Bobot CPMK'!$P$8,0),IF('Bobot CPMK'!$B$9='Peta CPL'!$A$17,N(I5)*'Bobot CPMK'!$P$9,0),IF('Bobot CPMK'!$B$10='Peta CPL'!$A$17,N(J5)*'Bobot CPMK'!$P$10,0),IF('Bobot CPMK'!$B$11='Peta CPL'!$A$17,N(K5)*'Bobot CPMK'!$P$11,0))/SUM(IF('Bobot CPMK'!$B$4='Peta CPL'!$A$17,'Bobot CPMK'!$P$4,0),IF('Bobot CPMK'!$B$5='Peta CPL'!$A$17,'Bobot CPMK'!$P$5,0),IF('Bobot CPMK'!$B$6='Peta CPL'!$A$17,'Bobot CPMK'!$P$6,0),IF('Bobot CPMK'!$B$7='Peta CPL'!$A$17,'Bobot CPMK'!$P$7,0),IF('Bobot CPMK'!$B$8='Peta CPL'!$A$17,'Bobot CPMK'!$P$8,0),IF('Bobot CPMK'!$B$9='Peta CPL'!$A$17,'Bobot CPMK'!$P$9,0),IF('Bobot CPMK'!$B$10='Peta CPL'!$A$17,'Bobot CPMK'!$P$10,0),IF('Bobot CPMK'!$B$11='Peta CPL'!$A$17,'Bobot CPMK'!$P$11,0)),"")) | P5: =IF(OR($B5="",'Peta CPL'!$A$18=""),"",IFERROR(SUM(IF('Bobot CPMK'!$B$4='Peta CPL'!$A$18,N(D5)*'Bobot CPMK'!$P$4,0),IF('Bobot CPMK'!$B$5='Peta CPL'!$A$18,N(E5)*'Bobot CPMK'!$P$5,0),IF('Bobot CPMK'!$B$6='Peta CPL'!$A$18,N(F5)*'Bobot CPMK'!$P$6,0),IF('Bobot CPMK'!$B$7='Peta CPL'!$A$18,N(G5)*'Bobot CPMK'!$P$7,0),IF('Bobot CPMK'!$B$8='Peta CPL'!$A$18,N(H5)*'Bobot CPMK'!$P$8,0),IF('Bobot CPMK'!$B$9='Peta CPL'!$A$18,N(I5)*'Bobot CPMK'!$P$9,0),IF('Bobot CPMK'!$B$10='Peta CPL'!$A$18,N(J5)*'Bobot CPMK'!$P$10,0),IF('Bobot CPMK'!$B$11='Peta CPL'!$A$18,N(K5)*'Bobot CPMK'!$P$11,0))/SUM(IF('Bobot CPMK'!$B$4='Peta CPL'!$A$18,'Bobot CPMK'!$P$4,0),IF('Bobot CPMK'!$B$5='Peta CPL'!$A$18,'Bobot CPMK'!$P$5,0),IF('Bobot CPMK'!$B$6='Peta CPL'!$A$18,'Bobot CPMK'!$P$6,0),IF('Bobot CPMK'!$B$7='Peta CPL'!$A$18,'Bobot CPMK'!$P$7,0),IF('Bobot CPMK'!$B$8='Peta CPL'!$A$18,'Bobot CPMK'!$P$8,0),IF('Bobot CPMK'!$B$9='Peta CPL'!$A$18,'Bobot CPMK'!$P$9,0),IF('Bobot CPMK'!$B$10='Peta CPL'!$A$18,'Bobot CPMK'!$P$10,0),IF('Bobot CPMK'!$B$11='Peta CPL'!$A$18,'Bobot CPMK'!$P$11,0)),"")) | Q5: =IF(OR($B5="",'Peta CPL'!$A$19=""),"",IFERROR(SUM(IF('Bobot CPMK'!$B$4='Peta CPL'!$A$19,N(D5)*'Bobot CPMK'!$P$4,0),IF('Bobot CPMK'!$B$5='Peta CPL'!$A$19,N(E5)*'Bobot CPMK'!$P$5,0),IF('Bobot CPMK'!$B$6='Peta CPL'!$A$19,N(F5)*'Bobot CPMK'!$P$6,0),IF('Bobot CPMK'!$B$7='Peta CPL'!$A$19,N(G5)*'Bobot CPMK'!$P$7,0),IF('Bobot CPMK'!$B$8='Peta CPL'!$A$19,N(H5)*'Bobot CPMK'!$P$8,0),IF('Bobot CPMK'!$B$9='Peta CPL'!$A$19,N(I5)*'Bobot CPMK'!$P$9,0),IF('Bobot CPMK'!$B$10='Peta CPL'!$A$19,N(J5)*'Bobot CPMK'!$P$10,0),IF('Bobot CPMK'!$B$11='Peta CPL'!$A$19,N(K5)*'Bobot CPMK'!$P$11,0))/SUM(IF('Bobot CPMK'!$B$4='Peta CPL'!$A$19,'Bobot CPMK'!$P$4,0),IF('Bobot CPMK'!$B$5='Peta CPL'!$A$19,'Bobot CPMK'!$P$5,0),IF('Bobot CPMK'!$B$6='Peta CPL'!$A$19,'Bobot CPMK'!$P$6,0),IF('Bobot CPMK'!$B$7='Peta CPL'!$A$19,'Bobot CPMK'!$P$7,0),IF('Bobot CPMK'!$B$8='Peta CPL'!$A$19,'Bobot CPMK'!$P$8,0),IF('Bobot CPMK'!$B$9='Peta CPL'!$A$19,'Bobot CPMK'!$P$9,0),IF('Bobot CPMK'!$B$10='Peta CPL'!$A$19,'Bobot CPMK'!$P$10,0),IF('Bobot CPMK'!$B$11='Peta CPL'!$A$19,'Bobot CPMK'!$P$11,0)),"")) | R5: =IF(OR($B5="",'Peta CPL'!$A$20=""),"",IFERROR(SUM(IF('Bobot CPMK'!$B$4='Peta CPL'!$A$20,N(D5)*'Bobot CPMK'!$P$4,0),IF('Bobot CPMK'!$B$5='Peta CPL'!$A$20,N(E5)*'Bobot CPMK'!$P$5,0),IF('Bobot CPMK'!$B$6='Peta CPL'!$A$20,N(F5)*'Bobot CPMK'!$P$6,0),IF('Bobot CPMK'!$B$7='Peta CPL'!$A$20,N(G5)*'Bobot CPMK'!$P$7,0),IF('Bobot CPMK'!$B$8='Peta CPL'!$A$20,N(H5)*'Bobot CPMK'!$P$8,0),IF('Bobot CPMK'!$B$9='Peta CPL'!$A$20,N(I5)*'Bobot CPMK'!$P$9,0),IF('Bobot CPMK'!$B$10='Peta CPL'!$A$20,N(J5)*'Bobot CPMK'!$P$10,0),IF('Bobot CPMK'!$B$11='Peta CPL'!$A$20,N(K5)*'Bobot CPMK'!$P$11,0))/SUM(IF('Bobot CPMK'!$B$4='Peta CPL'!$A$20,'Bobot CPMK'!$P$4,0),IF('Bobot CPMK'!$B$5='Peta CPL'!$A$20,'Bobot CPMK'!$P$5,0),IF('Bobot CPMK'!$B$6='Peta CPL'!$A$20,'Bobot CPMK'!$P$6,0),IF('Bobot CPMK'!$B$7='Peta CPL'!$A$20,'Bobot CPMK'!$P$7,0),IF('Bobot CPMK'!$B$8='Peta CPL'!$A$20,'Bobot CPMK'!$P$8,0),IF('Bobot CPMK'!$B$9='Peta CPL'!$A$20,'Bobot CPMK'!$P$9,0),IF('Bobot CPMK'!$B$10='Peta CPL'!$A$20,'Bobot CPMK'!$P$10,0),IF('Bobot CPMK'!$B$11='Peta CPL'!$A$20,'Bobot CPMK'!$P$11,0)),"")) | S5: =IF(OR($B5="",'Peta CPL'!$A$21=""),"",IFERROR(SUM(IF('Bobot CPMK'!$B$4='Peta CPL'!$A$21,N(D5)*'Bobot CPMK'!$P$4,0),IF('Bobot CPMK'!$B$5='Peta CPL'!$A$21,N(E5)*'Bobot CPMK'!$P$5,0),IF('Bobot CPMK'!$B$6='Peta CPL'!$A$21,N(F5)*'Bobot CPMK'!$P$6,0),IF('Bobot CPMK'!$B$7='Peta CPL'!$A$21,N(G5)*'Bobot CPMK'!$P$7,0),IF('Bobot CPMK'!$B$8='Peta CPL'!$A$21,N(H5)*'Bobot CPMK'!$P$8,0),IF('Bobot CPMK'!$B$9='Peta CPL'!$A$21,N(I5)*'Bobot CPMK'!$P$9,0),IF('Bobot CPMK'!$B$10='Peta CPL'!$A$21,N(J5)*'Bobot CPMK'!$P$10,0),IF('Bobot CPMK'!$B$11='Peta CPL'!$A$21,N(K5)*'Bobot CPMK'!$P$11,0))/SUM(IF('Bobot CPMK'!$B$4='Peta CPL'!$A$21,'Bobot CPMK'!$P$4,0),IF('Bobot CPMK'!$B$5='Peta CPL'!$A$21,'Bobot CPMK'!$P$5,0),IF('Bobot CPMK'!$B$6='Peta CPL'!$A$21,'Bobot CPMK'!$P$6,0),IF('Bobot CPMK'!$B$7='Peta CPL'!$A$21,'Bobot CPMK'!$P$7,0),IF('Bobot CPMK'!$B$8='Peta CPL'!$A$21,'Bobot CPMK'!$P$8,0),IF('Bobot CPMK'!$B$9='Peta CPL'!$A$21,'Bobot CPMK'!$P$9,0),IF('Bobot CPMK'!$B$10='Peta CPL'!$A$21,'Bobot CPMK'!$P$10,0),IF('Bobot CPMK'!$B$11='Peta CPL'!$A$21,'Bobot CPMK'!$P$11,0)),"")) | T5: =IF(OR($B5="",'Peta CPL'!$A$5=""),"",IFERROR((N(L5)*N('Peta CPL'!$C$14)*N('Peta CPL'!$D$14)+N(M5)*N('Peta CPL'!$C$15)*N('Peta CPL'!$D$15)+N(N5)*N('Peta CPL'!$C$16)*N('Peta CPL'!$D$16)+N(O5)*N('Peta CPL'!$C$17)*N('Peta CPL'!$D$17)+N(P5)*N('Peta CPL'!$C$18)*N('Peta CPL'!$D$18)+N(Q5)*N('Peta CPL'!$C$19)*N('Peta CPL'!$D$19)+N(R5)*N('Peta CPL'!$C$20)*N('Peta CPL'!$D$20)+N(S5)*N('Peta CPL'!$C$21)*N('Peta CPL'!$D$21))/(N('Peta CPL'!$C$14)*N('Peta CPL'!$D$14)+N('Peta CPL'!$C$15)*N('Peta CPL'!$D$15)+N('Peta CPL'!$C$16)*N('Peta CPL'!$D$16)+N('Peta CPL'!$C$17)*N('Peta CPL'!$D$17)+N('Peta CPL'!$C$18)*N('Peta CPL'!$D$18)+N('Peta CPL'!$C$19)*N('Peta CPL'!$D$19)+N('Peta CPL'!$C$20)*N('Peta CPL'!$D$20)+N('Peta CPL'!$C$21)*N('Peta CPL'!$D$21)),"")) | U5: =IF(OR($B5="",'Peta CPL'!$A$6=""),"",IFERROR((N(L5)*N('Peta CPL'!$C$14)*N('Peta CPL'!$E$14)+N(M5)*N('Peta CPL'!$C$15)*N('Peta CPL'!$E$15)+N(N5)*N('Peta CPL'!$C$16)*N('Peta CPL'!$E$16)+N(O5)*N('Peta CPL'!$C$17)*N('Peta CPL'!$E$17)+N(P5)*N('Peta CPL'!$C$18)*N('Peta CPL'!$E$18)+N(Q5)*N('Peta CPL'!$C$19)*N('Peta CPL'!$E$19)+N(R5)*N('Peta CPL'!$C$20)*N('Peta CPL'!$E$20)+N(S5)*N('Peta CPL'!$C$21)*N('Peta CPL'!$E$21))/(N('Peta CPL'!$C$14)*N('Peta CPL'!$E$14)+N('Peta CPL'!$C$15)*N('Peta CPL'!$E$15)+N('Peta CPL'!$C$16)*N('Peta CPL'!$E$16)+N('Peta CPL'!$C$17)*N('Peta CPL'!$E$17)+N('Peta CPL'!$C$18)*N('Peta CPL'!$E$18)+N('Peta CPL'!$C$19)*N('Peta CPL'!$E$19)+N('Peta CPL'!$C$20)*N('Peta CPL'!$E$20)+N('Peta CPL'!$C$21)*N('Peta CPL'!$E$21)),"")) | V5: =IF(OR($B5="",'Peta CPL'!$A$7=""),"",IFERROR((N(L5)*N('Peta CPL'!$C$14)*N('Peta CPL'!$F$14)+N(M5)*N('Peta CPL'!$C$15)*N('Peta CPL'!$F$15)+N(N5)*N('Peta CPL'!$C$16)*N('Peta CPL'!$F$16)+N(O5)*N('Peta CPL'!$C$17)*N('Peta CPL'!$F$17)+N(P5)*N('Peta CPL'!$C$18)*N('Peta CPL'!$F$18)+N(Q5)*N('Peta CPL'!$C$19)*N('Peta CPL'!$F$19)+N(R5)*N('Peta CPL'!$C$20)*N('Peta CPL'!$F$20)+N(S5)*N('Peta CPL'!$C$21)*N('Peta CPL'!$F$21))/(N('Peta CPL'!$C$14)*N('Peta CPL'!$F$14)+N('Peta CPL'!$C$15)*N('Peta CPL'!$F$15)+N('Peta CPL'!$C$16)*N('Peta CPL'!$F$16)+N('Peta CPL'!$C$17)*N('Peta CPL'!$F$17)+N('Peta CPL'!$C$18)*N('Peta CPL'!$F$18)+N('Peta CPL'!$C$19)*N('Peta CPL'!$F$19)+N('Peta CPL'!$C$20)*N('Peta CPL'!$F$20)+N('Peta CPL'!$C$21)*N('Peta CPL'!$F$21)),"")) | W5: =IF(OR($B5="",'Peta CPL'!$A$8=""),"",IFERROR((N(L5)*N('Peta CPL'!$C$14)*N('Peta CPL'!$G$14)+N(M5)*N('Peta CPL'!$C$15)*N('Peta CPL'!$G$15)+N(N5)*N('Peta CPL'!$C$16)*N('Peta CPL'!$G$16)+N(O5)*N('Peta CPL'!$C$17)*N('Peta CPL'!$G$17)+N(P5)*N('Peta CPL'!$C$18)*N('Peta CPL'!$G$18)+N(Q5)*N('Peta CPL'!$C$19)*N('Peta CPL'!$G$19)+N(R5)*N('Peta CPL'!$C$20)*N('Peta CPL'!$G$20)+N(S5)*N('Peta CPL'!$C$21)*N('Peta CPL'!$G$21))/(N('Peta CPL'!$C$14)*N('Peta CPL'!$G$14)+N('Peta CPL'!$C$15)*N('Peta CPL'!$G$15)+N('Peta CPL'!$C$16)*N('Peta CPL'!$G$16)+N('Peta CPL'!$C$17)*N('Peta CPL'!$G$17)+N('Peta CPL'!$C$18)*N('Peta CPL'!$G$18)+N('Peta CPL'!$C$19)*N('Peta CPL'!$G$19)+N('Peta CPL'!$C$20)*N('Peta CPL'!$G$20)+N('Peta CPL'!$C$21)*N('Peta CPL'!$G$21)),"")) | X5: =IF(OR($B5="",'Peta CPL'!$A$9=""),"",IFERROR((N(L5)*N('Peta CPL'!$C$14)*N('Peta CPL'!$H$14)+N(M5)*N('Peta CPL'!$C$15)*N('Peta CPL'!$H$15)+N(N5)*N('Peta CPL'!$C$16)*N('Peta CPL'!$H$16)+N(O5)*N('Peta CPL'!$C$17)*N('Peta CPL'!$H$17)+N(P5)*N('Peta CPL'!$C$18)*N('Peta CPL'!$H$18)+N(Q5)*N('Peta CPL'!$C$19)*N('Peta CPL'!$H$19)+N(R5)*N('Peta CPL'!$C$20)*N('Peta CPL'!$H$20)+N(S5)*N('Peta CPL'!$C$21)*N('Peta CPL'!$H$21))/(N('Peta CPL'!$C$14)*N('Peta CPL'!$H$14)+N('Peta CPL'!$C$15)*N('Peta CPL'!$H$15)+N('Peta CPL'!$C$16)*N('Peta CPL'!$H$16)+N('Peta CPL'!$C$17)*N('Peta CPL'!$H$17)+N('Peta CPL'!$C$18)*N('Peta CPL'!$H$18)+N('Peta CPL'!$C$19)*N('Peta CPL'!$H$19)+N('Peta CPL'!$C$20)*N('Peta CPL'!$H$20)+N('Peta CPL'!$C$21)*N('Peta CPL'!$H$21)),"")) | Y5: =IF(OR($B5="",'Peta CPL'!$A$10=""),"",IFERROR((N(L5)*N('Peta CPL'!$C$14)*N('Peta CPL'!$I$14)+N(M5)*N('Peta CPL'!$C$15)*N('Peta CPL'!$I$15)+N(N5)*N('Peta CPL'!$C$16)*N('Peta CPL'!$I$16)+N(O5)*N('Peta CPL'!$C$17)*N('Peta CPL'!$I$17)+N(P5)*N('Peta CPL'!$C$18)*N('Peta CPL'!$I$18)+N(Q5)*N('Peta CPL'!$C$19)*N('Peta CPL'!$I$19)+N(R5)*N('Peta CPL'!$C$20)*N('Peta CPL'!$I$20)+N(S5)*N('Peta CPL'!$C$21)*N('Peta CPL'!$I$21))/(N('Peta CPL'!$C$14)*N('Peta CPL'!$I$14)+N('Peta CPL'!$C$15)*N('Peta CPL'!$I$15)+N('Peta CPL'!$C$16)*N('Peta CPL'!$I$16)+N('Peta CPL'!$C$17)*N('Peta CPL'!$I$17)+N('Peta CPL'!$C$18)*N('Peta CPL'!$I$18)+N('Peta CPL'!$C$19)*N('Peta CPL'!$I$19)+N('Peta CPL'!$C$20)*N('Peta CPL'!$I$20)+N('Peta CPL'!$C$21)*N('Peta CPL'!$I$21)),"")) | Z5: =IF($B5="","",IFERROR((N(L5)*N('Peta CPL'!$C$14)+N(M5)*N('Peta CPL'!$C$15)+N(N5)*N('Peta CPL'!$C$16)+N(O5)*N('Peta CPL'!$C$17)+N(P5)*N('Peta CPL'!$C$18)+N(Q5)*N('Peta CPL'!$C$19)+N(R5)*N('Peta CPL'!$C$20)+N(S5)*N('Peta CPL'!$C$21))/100,""))
A6: ='Input Nilai'!A6 | B6: ='Input Nilai'!B6 | C6: ='Input Nilai'!C6 | D6: =IF(OR('Input Nilai'!$B6="",'Bobot CPMK'!$O$4=0),"",(SUMPRODUCT('Input Nilai'!D6:L6,'Bobot CPMK'!$E$4:$M$4)+'Input Nilai'!$BX6*'Bobot CPMK'!$N$4)/'Bobot CPMK'!$O$4) | E6: =IF(OR('Input Nilai'!$B6="",'Bobot CPMK'!$O$5=0),"",(SUMPRODUCT('Input Nilai'!M6:U6,'Bobot CPMK'!$E$5:$M$5)+'Input Nilai'!$BX6*'Bobot CPMK'!$N$5)/'Bobot CPMK'!$O$5) | F6: =IF(OR('Input Nilai'!$B6="",'Bobot CPMK'!$O$6=0),"",(SUMPRODUCT('Input Nilai'!V6:AD6,'Bobot CPMK'!$E$6:$M$6)+'Input Nilai'!$BX6*'Bobot CPMK'!$N$6)/'Bobot CPMK'!$O$6) | G6: =IF(OR('Input Nilai'!$B6="",'Bobot CPMK'!$O$7=0),"",(SUMPRODUCT('Input Nilai'!AE6:AM6,'Bobot CPMK'!$E$7:$M$7)+'Input Nilai'!$BX6*'Bobot CPMK'!$N$7)/'Bobot CPMK'!$O$7) | H6: =IF(OR('Input Nilai'!$B6="",'Bobot CPMK'!$O$8=0),"",(SUMPRODUCT('Input Nilai'!AN6:AV6,'Bobot CPMK'!$E$8:$M$8)+'Input Nilai'!$BX6*'Bobot CPMK'!$N$8)/'Bobot CPMK'!$O$8) | I6: =IF(OR('Input Nilai'!$B6="",'Bobot CPMK'!$O$9=0),"",(SUMPRODUCT('Input Nilai'!AW6:BE6,'Bobot CPMK'!$E$9:$M$9)+'Input Nilai'!$BX6*'Bobot CPMK'!$N$9)/'Bobot CPMK'!$O$9) | J6: =IF(OR('Input Nilai'!$B6="",'Bobot CPMK'!$O$10=0),"",(SUMPRODUCT('Input Nilai'!BF6:BN6,'Bobot CPMK'!$E$10:$M$10)+'Input Nilai'!$BX6*'Bobot CPMK'!$N$10)/'Bobot CPMK'!$O$10) | K6: =IF(OR('Input Nilai'!$B6="",'Bobot CPMK'!$O$11=0),"",(SUMPRODUCT('Input Nilai'!BO6:BW6,'Bobot CPMK'!$E$11:$M$11)+'Input Nilai'!$BX6*'Bobot CPMK'!$N$11)/'Bobot CPMK'!$O$11) | L6: =IF(OR($B6="",'Peta CPL'!$A$14=""),"",IFERROR(SUM(IF('Bobot CPMK'!$B$4='Peta CPL'!$A$14,N(D6)*'Bobot CPMK'!$P$4,0),IF('Bobot CPMK'!$B$5='Peta CPL'!$A$14,N(E6)*'Bobot CPMK'!$P$5,0),IF('Bobot CPMK'!$B$6='Peta CPL'!$A$14,N(F6)*'Bobot CPMK'!$P$6,0),IF('Bobot CPMK'!$B$7='Peta CPL'!$A$14,N(G6)*'Bobot CPMK'!$P$7,0),IF('Bobot CPMK'!$B$8='Peta CPL'!$A$14,N(H6)*'Bobot CPMK'!$P$8,0),IF('Bobot CPMK'!$B$9='Peta CPL'!$A$14,N(I6)*'Bobot CPMK'!$P$9,0),IF('Bobot CPMK'!$B$10='Peta CPL'!$A$14,N(J6)*'Bobot CPMK'!$P$10,0),IF('Bobot CPMK'!$B$11='Peta CPL'!$A$14,N(K6)*'Bobot CPMK'!$P$11,0))/SUM(IF('Bobot CPMK'!$B$4='Peta CPL'!$A$14,'Bobot CPMK'!$P$4,0),IF('Bobot CPMK'!$B$5='Peta CPL'!$A$14,'Bobot CPMK'!$P$5,0),IF('Bobot CPMK'!$B$6='Peta CPL'!$A$14,'Bobot CPMK'!$P$6,0),IF('Bobot CPMK'!$B$7='Peta CPL'!$A$14,'Bobot CPMK'!$P$7,0),IF('Bobot CPMK'!$B$8='Peta CPL'!$A$14,'Bobot CPMK'!$P$8,0),IF('Bobot CPMK'!$B$9='Peta CPL'!$A$14,'Bobot CPMK'!$P$9,0),IF('Bobot CPMK'!$B$10='Peta CPL'!$A$14,'Bobot CPMK'!$P$10,0),IF('Bobot CPMK'!$B$11='Peta CPL'!$A$14,'Bobot CPMK'!$P$11,0)),"")) | M6: =IF(OR($B6="",'Peta CPL'!$A$15=""),"",IFERROR(SUM(IF('Bobot CPMK'!$B$4='Peta CPL'!$A$15,N(D6)*'Bobot CPMK'!$P$4,0),IF('Bobot CPMK'!$B$5='Peta CPL'!$A$15,N(E6)*'Bobot CPMK'!$P$5,0),IF('Bobot CPMK'!$B$6='Peta CPL'!$A$15,N(F6)*'Bobot CPMK'!$P$6,0),IF('Bobot CPMK'!$B$7='Peta CPL'!$A$15,N(G6)*'Bobot CPMK'!$P$7,0),IF('Bobot CPMK'!$B$8='Peta CPL'!$A$15,N(H6)*'Bobot CPMK'!$P$8,0),IF('Bobot CPMK'!$B$9='Peta CPL'!$A$15,N(I6)*'Bobot CPMK'!$P$9,0),IF('Bobot CPMK'!$B$10='Peta CPL'!$A$15,N(J6)*'Bobot CPMK'!$P$10,0),IF('Bobot CPMK'!$B$11='Peta CPL'!$A$15,N(K6)*'Bobot CPMK'!$P$11,0))/SUM(IF('Bobot CPMK'!$B$4='Peta CPL'!$A$15,'Bobot CPMK'!$P$4,0),IF('Bobot CPMK'!$B$5='Peta CPL'!$A$15,'Bobot CPMK'!$P$5,0),IF('Bobot CPMK'!$B$6='Peta CPL'!$A$15,'Bobot CPMK'!$P$6,0),IF('Bobot CPMK'!$B$7='Peta CPL'!$A$15,'Bobot CPMK'!$P$7,0),IF('Bobot CPMK'!$B$8='Peta CPL'!$A$15,'Bobot CPMK'!$P$8,0),IF('Bobot CPMK'!$B$9='Peta CPL'!$A$15,'Bobot CPMK'!$P$9,0),IF('Bobot CPMK'!$B$10='Peta CPL'!$A$15,'Bobot CPMK'!$P$10,0),IF('Bobot CPMK'!$B$11='Peta CPL'!$A$15,'Bobot CPMK'!$P$11,0)),"")) | N6: =IF(OR($B6="",'Peta CPL'!$A$16=""),"",IFERROR(SUM(IF('Bobot CPMK'!$B$4='Peta CPL'!$A$16,N(D6)*'Bobot CPMK'!$P$4,0),IF('Bobot CPMK'!$B$5='Peta CPL'!$A$16,N(E6)*'Bobot CPMK'!$P$5,0),IF('Bobot CPMK'!$B$6='Peta CPL'!$A$16,N(F6)*'Bobot CPMK'!$P$6,0),IF('Bobot CPMK'!$B$7='Peta CPL'!$A$16,N(G6)*'Bobot CPMK'!$P$7,0),IF('Bobot CPMK'!$B$8='Peta CPL'!$A$16,N(H6)*'Bobot CPMK'!$P$8,0),IF('Bobot CPMK'!$B$9='Peta CPL'!$A$16,N(I6)*'Bobot CPMK'!$P$9,0),IF('Bobot CPMK'!$B$10='Peta CPL'!$A$16,N(J6)*'Bobot CPMK'!$P$10,0),IF('Bobot CPMK'!$B$11='Peta CPL'!$A$16,N(K6)*'Bobot CPMK'!$P$11,0))/SUM(IF('Bobot CPMK'!$B$4='Peta CPL'!$A$16,'Bobot CPMK'!$P$4,0),IF('Bobot CPMK'!$B$5='Peta CPL'!$A$16,'Bobot CPMK'!$P$5,0),IF('Bobot CPMK'!$B$6='Peta CPL'!$A$16,'Bobot CPMK'!$P$6,0),IF('Bobot CPMK'!$B$7='Peta CPL'!$A$16,'Bobot CPMK'!$P$7,0),IF('Bobot CPMK'!$B$8='Peta CPL'!$A$16,'Bobot CPMK'!$P$8,0),IF('Bobot CPMK'!$B$9='Peta CPL'!$A$16,'Bobot CPMK'!$P$9,0),IF('Bobot CPMK'!$B$10='Peta CPL'!$A$16,'Bobot CPMK'!$P$10,0),IF('Bobot CPMK'!$B$11='Peta CPL'!$A$16,'Bobot CPMK'!$P$11,0)),"")) | O6: =IF(OR($B6="",'Peta CPL'!$A$17=""),"",IFERROR(SUM(IF('Bobot CPMK'!$B$4='Peta CPL'!$A$17,N(D6)*'Bobot CPMK'!$P$4,0),IF('Bobot CPMK'!$B$5='Peta CPL'!$A$17,N(E6)*'Bobot CPMK'!$P$5,0),IF('Bobot CPMK'!$B$6='Peta CPL'!$A$17,N(F6)*'Bobot CPMK'!$P$6,0),IF('Bobot CPMK'!$B$7='Peta CPL'!$A$17,N(G6)*'Bobot CPMK'!$P$7,0),IF('Bobot CPMK'!$B$8='Peta CPL'!$A$17,N(H6)*'Bobot CPMK'!$P$8,0),IF('Bobot CPMK'!$B$9='Peta CPL'!$A$17,N(I6)*'Bobot CPMK'!$P$9,0),IF('Bobot CPMK'!$B$10='Peta CPL'!$A$17,N(J6)*'Bobot CPMK'!$P$10,0),IF('Bobot CPMK'!$B$11='Peta CPL'!$A$17,N(K6)*'Bobot CPMK'!$P$11,0))/SUM(IF('Bobot CPMK'!$B$4='Peta CPL'!$A$17,'Bobot CPMK'!$P$4,0),IF('Bobot CPMK'!$B$5='Peta CPL'!$A$17,'Bobot CPMK'!$P$5,0),IF('Bobot CPMK'!$B$6='Peta CPL'!$A$17,'Bobot CPMK'!$P$6,0),IF('Bobot CPMK'!$B$7='Peta CPL'!$A$17,'Bobot CPMK'!$P$7,0),IF('Bobot CPMK'!$B$8='Peta CPL'!$A$17,'Bobot CPMK'!$P$8,0),IF('Bobot CPMK'!$B$9='Peta CPL'!$A$17,'Bobot CPMK'!$P$9,0),IF('Bobot CPMK'!$B$10='Peta CPL'!$A$17,'Bobot CPMK'!$P$10,0),IF('Bobot CPMK'!$B$11='Peta CPL'!$A$17,'Bobot CPMK'!$P$11,0)),"")) | P6: =IF(OR($B6="",'Peta CPL'!$A$18=""),"",IFERROR(SUM(IF('Bobot CPMK'!$B$4='Peta CPL'!$A$18,N(D6)*'Bobot CPMK'!$P$4,0),IF('Bobot CPMK'!$B$5='Peta CPL'!$A$18,N(E6)*'Bobot CPMK'!$P$5,0),IF('Bobot CPMK'!$B$6='Peta CPL'!$A$18,N(F6)*'Bobot CPMK'!$P$6,0),IF('Bobot CPMK'!$B$7='Peta CPL'!$A$18,N(G6)*'Bobot CPMK'!$P$7,0),IF('Bobot CPMK'!$B$8='Peta CPL'!$A$18,N(H6)*'Bobot CPMK'!$P$8,0),IF('Bobot CPMK'!$B$9='Peta CPL'!$A$18,N(I6)*'Bobot CPMK'!$P$9,0),IF('Bobot CPMK'!$B$10='Peta CPL'!$A$18,N(J6)*'Bobot CPMK'!$P$10,0),IF('Bobot CPMK'!$B$11='Peta CPL'!$A$18,N(K6)*'Bobot CPMK'!$P$11,0))/SUM(IF('Bobot CPMK'!$B$4='Peta CPL'!$A$18,'Bobot CPMK'!$P$4,0),IF('Bobot CPMK'!$B$5='Peta CPL'!$A$18,'Bobot CPMK'!$P$5,0),IF('Bobot CPMK'!$B$6='Peta CPL'!$A$18,'Bobot CPMK'!$P$6,0),IF('Bobot CPMK'!$B$7='Peta CPL'!$A$18,'Bobot CPMK'!$P$7,0),IF('Bobot CPMK'!$B$8='Peta CPL'!$A$18,'Bobot CPMK'!$P$8,0),IF('Bobot CPMK'!$B$9='Peta CPL'!$A$18,'Bobot CPMK'!$P$9,0),IF('Bobot CPMK'!$B$10='Peta CPL'!$A$18,'Bobot CPMK'!$P$10,0),IF('Bobot CPMK'!$B$11='Peta CPL'!$A$18,'Bobot CPMK'!$P$11,0)),"")) | Q6: =IF(OR($B6="",'Peta CPL'!$A$19=""),"",IFERROR(SUM(IF('Bobot CPMK'!$B$4='Peta CPL'!$A$19,N(D6)*'Bobot CPMK'!$P$4,0),IF('Bobot CPMK'!$B$5='Peta CPL'!$A$19,N(E6)*'Bobot CPMK'!$P$5,0),IF('Bobot CPMK'!$B$6='Peta CPL'!$A$19,N(F6)*'Bobot CPMK'!$P$6,0),IF('Bobot CPMK'!$B$7='Peta CPL'!$A$19,N(G6)*'Bobot CPMK'!$P$7,0),IF('Bobot CPMK'!$B$8='Peta CPL'!$A$19,N(H6)*'Bobot CPMK'!$P$8,0),IF('Bobot CPMK'!$B$9='Peta CPL'!$A$19,N(I6)*'Bobot CPMK'!$P$9,0),IF('Bobot CPMK'!$B$10='Peta CPL'!$A$19,N(J6)*'Bobot CPMK'!$P$10,0),IF('Bobot CPMK'!$B$11='Peta CPL'!$A$19,N(K6)*'Bobot CPMK'!$P$11,0))/SUM(IF('Bobot CPMK'!$B$4='Peta CPL'!$A$19,'Bobot CPMK'!$P$4,0),IF('Bobot CPMK'!$B$5='Peta CPL'!$A$19,'Bobot CPMK'!$P$5,0),IF('Bobot CPMK'!$B$6='Peta CPL'!$A$19,'Bobot CPMK'!$P$6,0),IF('Bobot CPMK'!$B$7='Peta CPL'!$A$19,'Bobot CPMK'!$P$7,0),IF('Bobot CPMK'!$B$8='Peta CPL'!$A$19,'Bobot CPMK'!$P$8,0),IF('Bobot CPMK'!$B$9='Peta CPL'!$A$19,'Bobot CPMK'!$P$9,0),IF('Bobot CPMK'!$B$10='Peta CPL'!$A$19,'Bobot CPMK'!$P$10,0),IF('Bobot CPMK'!$B$11='Peta CPL'!$A$19,'Bobot CPMK'!$P$11,0)),"")) | R6: =IF(OR($B6="",'Peta CPL'!$A$20=""),"",IFERROR(SUM(IF('Bobot CPMK'!$B$4='Peta CPL'!$A$20,N(D6)*'Bobot CPMK'!$P$4,0),IF('Bobot CPMK'!$B$5='Peta CPL'!$A$20,N(E6)*'Bobot CPMK'!$P$5,0),IF('Bobot CPMK'!$B$6='Peta CPL'!$A$20,N(F6)*'Bobot CPMK'!$P$6,0),IF('Bobot CPMK'!$B$7='Peta CPL'!$A$20,N(G6)*'Bobot CPMK'!$P$7,0),IF('Bobot CPMK'!$B$8='Peta CPL'!$A$20,N(H6)*'Bobot CPMK'!$P$8,0),IF('Bobot CPMK'!$B$9='Peta CPL'!$A$20,N(I6)*'Bobot CPMK'!$P$9,0),IF('Bobot CPMK'!$B$10='Peta CPL'!$A$20,N(J6)*'Bobot CPMK'!$P$10,0),IF('Bobot CPMK'!$B$11='Peta CPL'!$A$20,N(K6)*'Bobot CPMK'!$P$11,0))/SUM(IF('Bobot CPMK'!$B$4='Peta CPL'!$A$20,'Bobot CPMK'!$P$4,0),IF('Bobot CPMK'!$B$5='Peta CPL'!$A$20,'Bobot CPMK'!$P$5,0),IF('Bobot CPMK'!$B$6='Peta CPL'!$A$20,'Bobot CPMK'!$P$6,0),IF('Bobot CPMK'!$B$7='Peta CPL'!$A$20,'Bobot CPMK'!$P$7,0),IF('Bobot CPMK'!$B$8='Peta CPL'!$A$20,'Bobot CPMK'!$P$8,0),IF('Bobot CPMK'!$B$9='Peta CPL'!$A$20,'Bobot CPMK'!$P$9,0),IF('Bobot CPMK'!$B$10='Peta CPL'!$A$20,'Bobot CPMK'!$P$10,0),IF('Bobot CPMK'!$B$11='Peta CPL'!$A$20,'Bobot CPMK'!$P$11,0)),"")) | S6: =IF(OR($B6="",'Peta CPL'!$A$21=""),"",IFERROR(SUM(IF('Bobot CPMK'!$B$4='Peta CPL'!$A$21,N(D6)*'Bobot CPMK'!$P$4,0),IF('Bobot CPMK'!$B$5='Peta CPL'!$A$21,N(E6)*'Bobot CPMK'!$P$5,0),IF('Bobot CPMK'!$B$6='Peta CPL'!$A$21,N(F6)*'Bobot CPMK'!$P$6,0),IF('Bobot CPMK'!$B$7='Peta CPL'!$A$21,N(G6)*'Bobot CPMK'!$P$7,0),IF('Bobot CPMK'!$B$8='Peta CPL'!$A$21,N(H6)*'Bobot CPMK'!$P$8,0),IF('Bobot CPMK'!$B$9='Peta CPL'!$A$21,N(I6)*'Bobot CPMK'!$P$9,0),IF('Bobot CPMK'!$B$10='Peta CPL'!$A$21,N(J6)*'Bobot CPMK'!$P$10,0),IF('Bobot CPMK'!$B$11='Peta CPL'!$A$21,N(K6)*'Bobot CPMK'!$P$11,0))/SUM(IF('Bobot CPMK'!$B$4='Peta CPL'!$A$21,'Bobot CPMK'!$P$4,0),IF('Bobot CPMK'!$B$5='Peta CPL'!$A$21,'Bobot CPMK'!$P$5,0),IF('Bobot CPMK'!$B$6='Peta CPL'!$A$21,'Bobot CPMK'!$P$6,0),IF('Bobot CPMK'!$B$7='Peta CPL'!$A$21,'Bobot CPMK'!$P$7,0),IF('Bobot CPMK'!$B$8='Peta CPL'!$A$21,'Bobot CPMK'!$P$8,0),IF('Bobot CPMK'!$B$9='Peta CPL'!$A$21,'Bobot CPMK'!$P$9,0),IF('Bobot CPMK'!$B$10='Peta CPL'!$A$21,'Bobot CPMK'!$P$10,0),IF('Bobot CPMK'!$B$11='Peta CPL'!$A$21,'Bobot CPMK'!$P$11,0)),"")) | T6: =IF(OR($B6="",'Peta CPL'!$A$5=""),"",IFERROR((N(L6)*N('Peta CPL'!$C$14)*N('Peta CPL'!$D$14)+N(M6)*N('Peta CPL'!$C$15)*N('Peta CPL'!$D$15)+N(N6)*N('Peta CPL'!$C$16)*N('Peta CPL'!$D$16)+N(O6)*N('Peta CPL'!$C$17)*N('Peta CPL'!$D$17)+N(P6)*N('Peta CPL'!$C$18)*N('Peta CPL'!$D$18)+N(Q6)*N('Peta CPL'!$C$19)*N('Peta CPL'!$D$19)+N(R6)*N('Peta CPL'!$C$20)*N('Peta CPL'!$D$20)+N(S6)*N('Peta CPL'!$C$21)*N('Peta CPL'!$D$21))/(N('Peta CPL'!$C$14)*N('Peta CPL'!$D$14)+N('Peta CPL'!$C$15)*N('Peta CPL'!$D$15)+N('Peta CPL'!$C$16)*N('Peta CPL'!$D$16)+N('Peta CPL'!$C$17)*N('Peta CPL'!$D$17)+N('Peta CPL'!$C$18)*N('Peta CPL'!$D$18)+N('Peta CPL'!$C$19)*N('Peta CPL'!$D$19)+N('Peta CPL'!$C$20)*N('Peta CPL'!$D$20)+N('Peta CPL'!$C$21)*N('Peta CPL'!$D$21)),"")) | U6: =IF(OR($B6="",'Peta CPL'!$A$6=""),"",IFERROR((N(L6)*N('Peta CPL'!$C$14)*N('Peta CPL'!$E$14)+N(M6)*N('Peta CPL'!$C$15)*N('Peta CPL'!$E$15)+N(N6)*N('Peta CPL'!$C$16)*N('Peta CPL'!$E$16)+N(O6)*N('Peta CPL'!$C$17)*N('Peta CPL'!$E$17)+N(P6)*N('Peta CPL'!$C$18)*N('Peta CPL'!$E$18)+N(Q6)*N('Peta CPL'!$C$19)*N('Peta CPL'!$E$19)+N(R6)*N('Peta CPL'!$C$20)*N('Peta CPL'!$E$20)+N(S6)*N('Peta CPL'!$C$21)*N('Peta CPL'!$E$21))/(N('Peta CPL'!$C$14)*N('Peta CPL'!$E$14)+N('Peta CPL'!$C$15)*N('Peta CPL'!$E$15)+N('Peta CPL'!$C$16)*N('Peta CPL'!$E$16)+N('Peta CPL'!$C$17)*N('Peta CPL'!$E$17)+N('Peta CPL'!$C$18)*N('Peta CPL'!$E$18)+N('Peta CPL'!$C$19)*N('Peta CPL'!$E$19)+N('Peta CPL'!$C$20)*N('Peta CPL'!$E$20)+N('Peta CPL'!$C$21)*N('Peta CPL'!$E$21)),"")) | V6: =IF(OR($B6="",'Peta CPL'!$A$7=""),"",IFERROR((N(L6)*N('Peta CPL'!$C$14)*N('Peta CPL'!$F$14)+N(M6)*N('Peta CPL'!$C$15)*N('Peta CPL'!$F$15)+N(N6)*N('Peta CPL'!$C$16)*N('Peta CPL'!$F$16)+N(O6)*N('Peta CPL'!$C$17)*N('Peta CPL'!$F$17)+N(P6)*N('Peta CPL'!$C$18)*N('Peta CPL'!$F$18)+N(Q6)*N('Peta CPL'!$C$19)*N('Peta CPL'!$F$19)+N(R6)*N('Peta CPL'!$C$20)*N('Peta CPL'!$F$20)+N(S6)*N('Peta CPL'!$C$21)*N('Peta CPL'!$F$21))/(N('Peta CPL'!$C$14)*N('Peta CPL'!$F$14)+N('Peta CPL'!$C$15)*N('Peta CPL'!$F$15)+N('Peta CPL'!$C$16)*N('Peta CPL'!$F$16)+N('Peta CPL'!$C$17)*N('Peta CPL'!$F$17)+N('Peta CPL'!$C$18)*N('Peta CPL'!$F$18)+N('Peta CPL'!$C$19)*N('Peta CPL'!$F$19)+N('Peta CPL'!$C$20)*N('Peta CPL'!$F$20)+N('Peta CPL'!$C$21)*N('Peta CPL'!$F$21)),"")) | W6: =IF(OR($B6="",'Peta CPL'!$A$8=""),"",IFERROR((N(L6)*N('Peta CPL'!$C$14)*N('Peta CPL'!$G$14)+N(M6)*N('Peta CPL'!$C$15)*N('Peta CPL'!$G$15)+N(N6)*N('Peta CPL'!$C$16)*N('Peta CPL'!$G$16)+N(O6)*N('Peta CPL'!$C$17)*N('Peta CPL'!$G$17)+N(P6)*N('Peta CPL'!$C$18)*N('Peta CPL'!$G$18)+N(Q6)*N('Peta CPL'!$C$19)*N('Peta CPL'!$G$19)+N(R6)*N('Peta CPL'!$C$20)*N('Peta CPL'!$G$20)+N(S6)*N('Peta CPL'!$C$21)*N('Peta CPL'!$G$21))/(N('Peta CPL'!$C$14)*N('Peta CPL'!$G$14)+N('Peta CPL'!$C$15)*N('Peta CPL'!$G$15)+N('Peta CPL'!$C$16)*N('Peta CPL'!$G$16)+N('Peta CPL'!$C$17)*N('Peta CPL'!$G$17)+N('Peta CPL'!$C$18)*N('Peta CPL'!$G$18)+N('Peta CPL'!$C$19)*N('Peta CPL'!$G$19)+N('Peta CPL'!$C$20)*N('Peta CPL'!$G$20)+N('Peta CPL'!$C$21)*N('Peta CPL'!$G$21)),"")) | X6: =IF(OR($B6="",'Peta CPL'!$A$9=""),"",IFERROR((N(L6)*N('Peta CPL'!$C$14)*N('Peta CPL'!$H$14)+N(M6)*N('Peta CPL'!$C$15)*N('Peta CPL'!$H$15)+N(N6)*N('Peta CPL'!$C$16)*N('Peta CPL'!$H$16)+N(O6)*N('Peta CPL'!$C$17)*N('Peta CPL'!$H$17)+N(P6)*N('Peta CPL'!$C$18)*N('Peta CPL'!$H$18)+N(Q6)*N('Peta CPL'!$C$19)*N('Peta CPL'!$H$19)+N(R6)*N('Peta CPL'!$C$20)*N('Peta CPL'!$H$20)+N(S6)*N('Peta CPL'!$C$21)*N('Peta CPL'!$H$21))/(N('Peta CPL'!$C$14)*N('Peta CPL'!$H$14)+N('Peta CPL'!$C$15)*N('Peta CPL'!$H$15)+N('Peta CPL'!$C$16)*N('Peta CPL'!$H$16)+N('Peta CPL'!$C$17)*N('Peta CPL'!$H$17)+N('Peta CPL'!$C$18)*N('Peta CPL'!$H$18)+N('Peta CPL'!$C$19)*N('Peta CPL'!$H$19)+N('Peta CPL'!$C$20)*N('Peta CPL'!$H$20)+N('Peta CPL'!$C$21)*N('Peta CPL'!$H$21)),"")) | Y6: =IF(OR($B6="",'Peta CPL'!$A$10=""),"",IFERROR((N(L6)*N('Peta CPL'!$C$14)*N('Peta CPL'!$I$14)+N(M6)*N('Peta CPL'!$C$15)*N('Peta CPL'!$I$15)+N(N6)*N('Peta CPL'!$C$16)*N('Peta CPL'!$I$16)+N(O6)*N('Peta CPL'!$C$17)*N('Peta CPL'!$I$17)+N(P6)*N('Peta CPL'!$C$18)*N('Peta CPL'!$I$18)+N(Q6)*N('Peta CPL'!$C$19)*N('Peta CPL'!$I$19)+N(R6)*N('Peta CPL'!$C$20)*N('Peta CPL'!$I$20)+N(S6)*N('Peta CPL'!$C$21)*N('Peta CPL'!$I$21))/(N('Peta CPL'!$C$14)*N('Peta CPL'!$I$14)+N('Peta CPL'!$C$15)*N('Peta CPL'!$I$15)+N('Peta CPL'!$C$16)*N('Peta CPL'!$I$16)+N('Peta CPL'!$C$17)*N('Peta CPL'!$I$17)+N('Peta CPL'!$C$18)*N('Peta CPL'!$I$18)+N('Peta CPL'!$C$19)*N('Peta CPL'!$I$19)+N('Peta CPL'!$C$20)*N('Peta CPL'!$I$20)+N('Peta CPL'!$C$21)*N('Peta CPL'!$I$21)),"")) | Z6: =IF($B6="","",IFERROR((N(L6)*N('Peta CPL'!$C$14)+N(M6)*N('Peta CPL'!$C$15)+N(N6)*N('Peta CPL'!$C$16)+N(O6)*N('Peta CPL'!$C$17)+N(P6)*N('Peta CPL'!$C$18)+N(Q6)*N('Peta CPL'!$C$19)+N(R6)*N('Peta CPL'!$C$20)+N(S6)*N('Peta CPL'!$C$21))/100,""))
A7: ='Input Nilai'!A7 | B7: ='Input Nilai'!B7 | C7: ='Input Nilai'!C7 | D7: =IF(OR('Input Nilai'!$B7="",'Bobot CPMK'!$O$4=0),"",(SUMPRODUCT('Input Nilai'!D7:L7,'Bobot CPMK'!$E$4:$M$4)+'Input Nilai'!$BX7*'Bobot CPMK'!$N$4)/'Bobot CPMK'!$O$4) | E7: =IF(OR('Input Nilai'!$B7="",'Bobot CPMK'!$O$5=0),"",(SUMPRODUCT('Input Nilai'!M7:U7,'Bobot CPMK'!$E$5:$M$5)+'Input Nilai'!$BX7*'Bobot CPMK'!$N$5)/'Bobot CPMK'!$O$5) | F7: =IF(OR('Input Nilai'!$B7="",'Bobot CPMK'!$O$6=0),"",(SUMPRODUCT('Input Nilai'!V7:AD7,'Bobot CPMK'!$E$6:$M$6)+'Input Nilai'!$BX7*'Bobot CPMK'!$N$6)/'Bobot CPMK'!$O$6) | G7: =IF(OR('Input Nilai'!$B7="",'Bobot CPMK'!$O$7=0),"",(SUMPRODUCT('Input Nilai'!AE7:AM7,'Bobot CPMK'!$E$7:$M$7)+'Input Nilai'!$BX7*'Bobot CPMK'!$N$7)/'Bobot CPMK'!$O$7) | H7: =IF(OR('Input Nilai'!$B7="",'Bobot CPMK'!$O$8=0),"",(SUMPRODUCT('Input Nilai'!AN7:AV7,'Bobot CPMK'!$E$8:$M$8)+'Input Nilai'!$BX7*'Bobot CPMK'!$N$8)/'Bobot CPMK'!$O$8) | I7: =IF(OR('Input Nilai'!$B7="",'Bobot CPMK'!$O$9=0),"",(SUMPRODUCT('Input Nilai'!AW7:BE7,'Bobot CPMK'!$E$9:$M$9)+'Input Nilai'!$BX7*'Bobot CPMK'!$N$9)/'Bobot CPMK'!$O$9) | J7: =IF(OR('Input Nilai'!$B7="",'Bobot CPMK'!$O$10=0),"",(SUMPRODUCT('Input Nilai'!BF7:BN7,'Bobot CPMK'!$E$10:$M$10)+'Input Nilai'!$BX7*'Bobot CPMK'!$N$10)/'Bobot CPMK'!$O$10) | K7: =IF(OR('Input Nilai'!$B7="",'Bobot CPMK'!$O$11=0),"",(SUMPRODUCT('Input Nilai'!BO7:BW7,'Bobot CPMK'!$E$11:$M$11)+'Input Nilai'!$BX7*'Bobot CPMK'!$N$11)/'Bobot CPMK'!$O$11) | L7: =IF(OR($B7="",'Peta CPL'!$A$14=""),"",IFERROR(SUM(IF('Bobot CPMK'!$B$4='Peta CPL'!$A$14,N(D7)*'Bobot CPMK'!$P$4,0),IF('Bobot CPMK'!$B$5='Peta CPL'!$A$14,N(E7)*'Bobot CPMK'!$P$5,0),IF('Bobot CPMK'!$B$6='Peta CPL'!$A$14,N(F7)*'Bobot CPMK'!$P$6,0),IF('Bobot CPMK'!$B$7='Peta CPL'!$A$14,N(G7)*'Bobot CPMK'!$P$7,0),IF('Bobot CPMK'!$B$8='Peta CPL'!$A$14,N(H7)*'Bobot CPMK'!$P$8,0),IF('Bobot CPMK'!$B$9='Peta CPL'!$A$14,N(I7)*'Bobot CPMK'!$P$9,0),IF('Bobot CPMK'!$B$10='Peta CPL'!$A$14,N(J7)*'Bobot CPMK'!$P$10,0),IF('Bobot CPMK'!$B$11='Peta CPL'!$A$14,N(K7)*'Bobot CPMK'!$P$11,0))/SUM(IF('Bobot CPMK'!$B$4='Peta CPL'!$A$14,'Bobot CPMK'!$P$4,0),IF('Bobot CPMK'!$B$5='Peta CPL'!$A$14,'Bobot CPMK'!$P$5,0),IF('Bobot CPMK'!$B$6='Peta CPL'!$A$14,'Bobot CPMK'!$P$6,0),IF('Bobot CPMK'!$B$7='Peta CPL'!$A$14,'Bobot CPMK'!$P$7,0),IF('Bobot CPMK'!$B$8='Peta CPL'!$A$14,'Bobot CPMK'!$P$8,0),IF('Bobot CPMK'!$B$9='Peta CPL'!$A$14,'Bobot CPMK'!$P$9,0),IF('Bobot CPMK'!$B$10='Peta CPL'!$A$14,'Bobot CPMK'!$P$10,0),IF('Bobot CPMK'!$B$11='Peta CPL'!$A$14,'Bobot CPMK'!$P$11,0)),"")) | M7: =IF(OR($B7="",'Peta CPL'!$A$15=""),"",IFERROR(SUM(IF('Bobot CPMK'!$B$4='Peta CPL'!$A$15,N(D7)*'Bobot CPMK'!$P$4,0),IF('Bobot CPMK'!$B$5='Peta CPL'!$A$15,N(E7)*'Bobot CPMK'!$P$5,0),IF('Bobot CPMK'!$B$6='Peta CPL'!$A$15,N(F7)*'Bobot CPMK'!$P$6,0),IF('Bobot CPMK'!$B$7='Peta CPL'!$A$15,N(G7)*'Bobot CPMK'!$P$7,0),IF('Bobot CPMK'!$B$8='Peta CPL'!$A$15,N(H7)*'Bobot CPMK'!$P$8,0),IF('Bobot CPMK'!$B$9='Peta CPL'!$A$15,N(I7)*'Bobot CPMK'!$P$9,0),IF('Bobot CPMK'!$B$10='Peta CPL'!$A$15,N(J7)*'Bobot CPMK'!$P$10,0),IF('Bobot CPMK'!$B$11='Peta CPL'!$A$15,N(K7)*'Bobot CPMK'!$P$11,0))/SUM(IF('Bobot CPMK'!$B$4='Peta CPL'!$A$15,'Bobot CPMK'!$P$4,0),IF('Bobot CPMK'!$B$5='Peta CPL'!$A$15,'Bobot CPMK'!$P$5,0),IF('Bobot CPMK'!$B$6='Peta CPL'!$A$15,'Bobot CPMK'!$P$6,0),IF('Bobot CPMK'!$B$7='Peta CPL'!$A$15,'Bobot CPMK'!$P$7,0),IF('Bobot CPMK'!$B$8='Peta CPL'!$A$15,'Bobot CPMK'!$P$8,0),IF('Bobot CPMK'!$B$9='Peta CPL'!$A$15,'Bobot CPMK'!$P$9,0),IF('Bobot CPMK'!$B$10='Peta CPL'!$A$15,'Bobot CPMK'!$P$10,0),IF('Bobot CPMK'!$B$11='Peta CPL'!$A$15,'Bobot CPMK'!$P$11,0)),"")) | N7: =IF(OR($B7="",'Peta CPL'!$A$16=""),"",IFERROR(SUM(IF('Bobot CPMK'!$B$4='Peta CPL'!$A$16,N(D7)*'Bobot CPMK'!$P$4,0),IF('Bobot CPMK'!$B$5='Peta CPL'!$A$16,N(E7)*'Bobot CPMK'!$P$5,0),IF('Bobot CPMK'!$B$6='Peta CPL'!$A$16,N(F7)*'Bobot CPMK'!$P$6,0),IF('Bobot CPMK'!$B$7='Peta CPL'!$A$16,N(G7)*'Bobot CPMK'!$P$7,0),IF('Bobot CPMK'!$B$8='Peta CPL'!$A$16,N(H7)*'Bobot CPMK'!$P$8,0),IF('Bobot CPMK'!$B$9='Peta CPL'!$A$16,N(I7)*'Bobot CPMK'!$P$9,0),IF('Bobot CPMK'!$B$10='Peta CPL'!$A$16,N(J7)*'Bobot CPMK'!$P$10,0),IF('Bobot CPMK'!$B$11='Peta CPL'!$A$16,N(K7)*'Bobot CPMK'!$P$11,0))/SUM(IF('Bobot CPMK'!$B$4='Peta CPL'!$A$16,'Bobot CPMK'!$P$4,0),IF('Bobot CPMK'!$B$5='Peta CPL'!$A$16,'Bobot CPMK'!$P$5,0),IF('Bobot CPMK'!$B$6='Peta CPL'!$A$16,'Bobot CPMK'!$P$6,0),IF('Bobot CPMK'!$B$7='Peta CPL'!$A$16,'Bobot CPMK'!$P$7,0),IF('Bobot CPMK'!$B$8='Peta CPL'!$A$16,'Bobot CPMK'!$P$8,0),IF('Bobot CPMK'!$B$9='Peta CPL'!$A$16,'Bobot CPMK'!$P$9,0),IF('Bobot CPMK'!$B$10='Peta CPL'!$A$16,'Bobot CPMK'!$P$10,0),IF('Bobot CPMK'!$B$11='Peta CPL'!$A$16,'Bobot CPMK'!$P$11,0)),"")) | O7: =IF(OR($B7="",'Peta CPL'!$A$17=""),"",IFERROR(SUM(IF('Bobot CPMK'!$B$4='Peta CPL'!$A$17,N(D7)*'Bobot CPMK'!$P$4,0),IF('Bobot CPMK'!$B$5='Peta CPL'!$A$17,N(E7)*'Bobot CPMK'!$P$5,0),IF('Bobot CPMK'!$B$6='Peta CPL'!$A$17,N(F7)*'Bobot CPMK'!$P$6,0),IF('Bobot CPMK'!$B$7='Peta CPL'!$A$17,N(G7)*'Bobot CPMK'!$P$7,0),IF('Bobot CPMK'!$B$8='Peta CPL'!$A$17,N(H7)*'Bobot CPMK'!$P$8,0),IF('Bobot CPMK'!$B$9='Peta CPL'!$A$17,N(I7)*'Bobot CPMK'!$P$9,0),IF('Bobot CPMK'!$B$10='Peta CPL'!$A$17,N(J7)*'Bobot CPMK'!$P$10,0),IF('Bobot CPMK'!$B$11='Peta CPL'!$A$17,N(K7)*'Bobot CPMK'!$P$11,0))/SUM(IF('Bobot CPMK'!$B$4='Peta CPL'!$A$17,'Bobot CPMK'!$P$4,0),IF('Bobot CPMK'!$B$5='Peta CPL'!$A$17,'Bobot CPMK'!$P$5,0),IF('Bobot CPMK'!$B$6='Peta CPL'!$A$17,'Bobot CPMK'!$P$6,0),IF('Bobot CPMK'!$B$7='Peta CPL'!$A$17,'Bobot CPMK'!$P$7,0),IF('Bobot CPMK'!$B$8='Peta CPL'!$A$17,'Bobot CPMK'!$P$8,0),IF('Bobot CPMK'!$B$9='Peta CPL'!$A$17,'Bobot CPMK'!$P$9,0),IF('Bobot CPMK'!$B$10='Peta CPL'!$A$17,'Bobot CPMK'!$P$10,0),IF('Bobot CPMK'!$B$11='Peta CPL'!$A$17,'Bobot CPMK'!$P$11,0)),"")) | P7: =IF(OR($B7="",'Peta CPL'!$A$18=""),"",IFERROR(SUM(IF('Bobot CPMK'!$B$4='Peta CPL'!$A$18,N(D7)*'Bobot CPMK'!$P$4,0),IF('Bobot CPMK'!$B$5='Peta CPL'!$A$18,N(E7)*'Bobot CPMK'!$P$5,0),IF('Bobot CPMK'!$B$6='Peta CPL'!$A$18,N(F7)*'Bobot CPMK'!$P$6,0),IF('Bobot CPMK'!$B$7='Peta CPL'!$A$18,N(G7)*'Bobot CPMK'!$P$7,0),IF('Bobot CPMK'!$B$8='Peta CPL'!$A$18,N(H7)*'Bobot CPMK'!$P$8,0),IF('Bobot CPMK'!$B$9='Peta CPL'!$A$18,N(I7)*'Bobot CPMK'!$P$9,0),IF('Bobot CPMK'!$B$10='Peta CPL'!$A$18,N(J7)*'Bobot CPMK'!$P$10,0),IF('Bobot CPMK'!$B$11='Peta CPL'!$A$18,N(K7)*'Bobot CPMK'!$P$11,0))/SUM(IF('Bobot CPMK'!$B$4='Peta CPL'!$A$18,'Bobot CPMK'!$P$4,0),IF('Bobot CPMK'!$B$5='Peta CPL'!$A$18,'Bobot CPMK'!$P$5,0),IF('Bobot CPMK'!$B$6='Peta CPL'!$A$18,'Bobot CPMK'!$P$6,0),IF('Bobot CPMK'!$B$7='Peta CPL'!$A$18,'Bobot CPMK'!$P$7,0),IF('Bobot CPMK'!$B$8='Peta CPL'!$A$18,'Bobot CPMK'!$P$8,0),IF('Bobot CPMK'!$B$9='Peta CPL'!$A$18,'Bobot CPMK'!$P$9,0),IF('Bobot CPMK'!$B$10='Peta CPL'!$A$18,'Bobot CPMK'!$P$10,0),IF('Bobot CPMK'!$B$11='Peta CPL'!$A$18,'Bobot CPMK'!$P$11,0)),"")) | Q7: =IF(OR($B7="",'Peta CPL'!$A$19=""),"",IFERROR(SUM(IF('Bobot CPMK'!$B$4='Peta CPL'!$A$19,N(D7)*'Bobot CPMK'!$P$4,0),IF('Bobot CPMK'!$B$5='Peta CPL'!$A$19,N(E7)*'Bobot CPMK'!$P$5,0),IF('Bobot CPMK'!$B$6='Peta CPL'!$A$19,N(F7)*'Bobot CPMK'!$P$6,0),IF('Bobot CPMK'!$B$7='Peta CPL'!$A$19,N(G7)*'Bobot CPMK'!$P$7,0),IF('Bobot CPMK'!$B$8='Peta CPL'!$A$19,N(H7)*'Bobot CPMK'!$P$8,0),IF('Bobot CPMK'!$B$9='Peta CPL'!$A$19,N(I7)*'Bobot CPMK'!$P$9,0),IF('Bobot CPMK'!$B$10='Peta CPL'!$A$19,N(J7)*'Bobot CPMK'!$P$10,0),IF('Bobot CPMK'!$B$11='Peta CPL'!$A$19,N(K7)*'Bobot CPMK'!$P$11,0))/SUM(IF('Bobot CPMK'!$B$4='Peta CPL'!$A$19,'Bobot CPMK'!$P$4,0),IF('Bobot CPMK'!$B$5='Peta CPL'!$A$19,'Bobot CPMK'!$P$5,0),IF('Bobot CPMK'!$B$6='Peta CPL'!$A$19,'Bobot CPMK'!$P$6,0),IF('Bobot CPMK'!$B$7='Peta CPL'!$A$19,'Bobot CPMK'!$P$7,0),IF('Bobot CPMK'!$B$8='Peta CPL'!$A$19,'Bobot CPMK'!$P$8,0),IF('Bobot CPMK'!$B$9='Peta CPL'!$A$19,'Bobot CPMK'!$P$9,0),IF('Bobot CPMK'!$B$10='Peta CPL'!$A$19,'Bobot CPMK'!$P$10,0),IF('Bobot CPMK'!$B$11='Peta CPL'!$A$19,'Bobot CPMK'!$P$11,0)),"")) | R7: =IF(OR($B7="",'Peta CPL'!$A$20=""),"",IFERROR(SUM(IF('Bobot CPMK'!$B$4='Peta CPL'!$A$20,N(D7)*'Bobot CPMK'!$P$4,0),IF('Bobot CPMK'!$B$5='Peta CPL'!$A$20,N(E7)*'Bobot CPMK'!$P$5,0),IF('Bobot CPMK'!$B$6='Peta CPL'!$A$20,N(F7)*'Bobot CPMK'!$P$6,0),IF('Bobot CPMK'!$B$7='Peta CPL'!$A$20,N(G7)*'Bobot CPMK'!$P$7,0),IF('Bobot CPMK'!$B$8='Peta CPL'!$A$20,N(H7)*'Bobot CPMK'!$P$8,0),IF('Bobot CPMK'!$B$9='Peta CPL'!$A$20,N(I7)*'Bobot CPMK'!$P$9,0),IF('Bobot CPMK'!$B$10='Peta CPL'!$A$20,N(J7)*'Bobot CPMK'!$P$10,0),IF('Bobot CPMK'!$B$11='Peta CPL'!$A$20,N(K7)*'Bobot CPMK'!$P$11,0))/SUM(IF('Bobot CPMK'!$B$4='Peta CPL'!$A$20,'Bobot CPMK'!$P$4,0),IF('Bobot CPMK'!$B$5='Peta CPL'!$A$20,'Bobot CPMK'!$P$5,0),IF('Bobot CPMK'!$B$6='Peta CPL'!$A$20,'Bobot CPMK'!$P$6,0),IF('Bobot CPMK'!$B$7='Peta CPL'!$A$20,'Bobot CPMK'!$P$7,0),IF('Bobot CPMK'!$B$8='Peta CPL'!$A$20,'Bobot CPMK'!$P$8,0),IF('Bobot CPMK'!$B$9='Peta CPL'!$A$20,'Bobot CPMK'!$P$9,0),IF('Bobot CPMK'!$B$10='Peta CPL'!$A$20,'Bobot CPMK'!$P$10,0),IF('Bobot CPMK'!$B$11='Peta CPL'!$A$20,'Bobot CPMK'!$P$11,0)),"")) | S7: =IF(OR($B7="",'Peta CPL'!$A$21=""),"",IFERROR(SUM(IF('Bobot CPMK'!$B$4='Peta CPL'!$A$21,N(D7)*'Bobot CPMK'!$P$4,0),IF('Bobot CPMK'!$B$5='Peta CPL'!$A$21,N(E7)*'Bobot CPMK'!$P$5,0),IF('Bobot CPMK'!$B$6='Peta CPL'!$A$21,N(F7)*'Bobot CPMK'!$P$6,0),IF('Bobot CPMK'!$B$7='Peta CPL'!$A$21,N(G7)*'Bobot CPMK'!$P$7,0),IF('Bobot CPMK'!$B$8='Peta CPL'!$A$21,N(H7)*'Bobot CPMK'!$P$8,0),IF('Bobot CPMK'!$B$9='Peta CPL'!$A$21,N(I7)*'Bobot CPMK'!$P$9,0),IF('Bobot CPMK'!$B$10='Peta CPL'!$A$21,N(J7)*'Bobot CPMK'!$P$10,0),IF('Bobot CPMK'!$B$11='Peta CPL'!$A$21,N(K7)*'Bobot CPMK'!$P$11,0))/SUM(IF('Bobot CPMK'!$B$4='Peta CPL'!$A$21,'Bobot CPMK'!$P$4,0),IF('Bobot CPMK'!$B$5='Peta CPL'!$A$21,'Bobot CPMK'!$P$5,0),IF('Bobot CPMK'!$B$6='Peta CPL'!$A$21,'Bobot CPMK'!$P$6,0),IF('Bobot CPMK'!$B$7='Peta CPL'!$A$21,'Bobot CPMK'!$P$7,0),IF('Bobot CPMK'!$B$8='Peta CPL'!$A$21,'Bobot CPMK'!$P$8,0),IF('Bobot CPMK'!$B$9='Peta CPL'!$A$21,'Bobot CPMK'!$P$9,0),IF('Bobot CPMK'!$B$10='Peta CPL'!$A$21,'Bobot CPMK'!$P$10,0),IF('Bobot CPMK'!$B$11='Peta CPL'!$A$21,'Bobot CPMK'!$P$11,0)),"")) | T7: =IF(OR($B7="",'Peta CPL'!$A$5=""),"",IFERROR((N(L7)*N('Peta CPL'!$C$14)*N('Peta CPL'!$D$14)+N(M7)*N('Peta CPL'!$C$15)*N('Peta CPL'!$D$15)+N(N7)*N('Peta CPL'!$C$16)*N('Peta CPL'!$D$16)+N(O7)*N('Peta CPL'!$C$17)*N('Peta CPL'!$D$17)+N(P7)*N('Peta CPL'!$C$18)*N('Peta CPL'!$D$18)+N(Q7)*N('Peta CPL'!$C$19)*N('Peta CPL'!$D$19)+N(R7)*N('Peta CPL'!$C$20)*N('Peta CPL'!$D$20)+N(S7)*N('Peta CPL'!$C$21)*N('Peta CPL'!$D$21))/(N('Peta CPL'!$C$14)*N('Peta CPL'!$D$14)+N('Peta CPL'!$C$15)*N('Peta CPL'!$D$15)+N('Peta CPL'!$C$16)*N('Peta CPL'!$D$16)+N('Peta CPL'!$C$17)*N('Peta CPL'!$D$17)+N('Peta CPL'!$C$18)*N('Peta CPL'!$D$18)+N('Peta CPL'!$C$19)*N('Peta CPL'!$D$19)+N('Peta CPL'!$C$20)*N('Peta CPL'!$D$20)+N('Peta CPL'!$C$21)*N('Peta CPL'!$D$21)),"")) | U7: =IF(OR($B7="",'Peta CPL'!$A$6=""),"",IFERROR((N(L7)*N('Peta CPL'!$C$14)*N('Peta CPL'!$E$14)+N(M7)*N('Peta CPL'!$C$15)*N('Peta CPL'!$E$15)+N(N7)*N('Peta CPL'!$C$16)*N('Peta CPL'!$E$16)+N(O7)*N('Peta CPL'!$C$17)*N('Peta CPL'!$E$17)+N(P7)*N('Peta CPL'!$C$18)*N('Peta CPL'!$E$18)+N(Q7)*N('Peta CPL'!$C$19)*N('Peta CPL'!$E$19)+N(R7)*N('Peta CPL'!$C$20)*N('Peta CPL'!$E$20)+N(S7)*N('Peta CPL'!$C$21)*N('Peta CPL'!$E$21))/(N('Peta CPL'!$C$14)*N('Peta CPL'!$E$14)+N('Peta CPL'!$C$15)*N('Peta CPL'!$E$15)+N('Peta CPL'!$C$16)*N('Peta CPL'!$E$16)+N('Peta CPL'!$C$17)*N('Peta CPL'!$E$17)+N('Peta CPL'!$C$18)*N('Peta CPL'!$E$18)+N('Peta CPL'!$C$19)*N('Peta CPL'!$E$19)+N('Peta CPL'!$C$20)*N('Peta CPL'!$E$20)+N('Peta CPL'!$C$21)*N('Peta CPL'!$E$21)),"")) | V7: =IF(OR($B7="",'Peta CPL'!$A$7=""),"",IFERROR((N(L7)*N('Peta CPL'!$C$14)*N('Peta CPL'!$F$14)+N(M7)*N('Peta CPL'!$C$15)*N('Peta CPL'!$F$15)+N(N7)*N('Peta CPL'!$C$16)*N('Peta CPL'!$F$16)+N(O7)*N('Peta CPL'!$C$17)*N('Peta CPL'!$F$17)+N(P7)*N('Peta CPL'!$C$18)*N('Peta CPL'!$F$18)+N(Q7)*N('Peta CPL'!$C$19)*N('Peta CPL'!$F$19)+N(R7)*N('Peta CPL'!$C$20)*N('Peta CPL'!$F$20)+N(S7)*N('Peta CPL'!$C$21)*N('Peta CPL'!$F$21))/(N('Peta CPL'!$C$14)*N('Peta CPL'!$F$14)+N('Peta CPL'!$C$15)*N('Peta CPL'!$F$15)+N('Peta CPL'!$C$16)*N('Peta CPL'!$F$16)+N('Peta CPL'!$C$17)*N('Peta CPL'!$F$17)+N('Peta CPL'!$C$18)*N('Peta CPL'!$F$18)+N('Peta CPL'!$C$19)*N('Peta CPL'!$F$19)+N('Peta CPL'!$C$20)*N('Peta CPL'!$F$20)+N('Peta CPL'!$C$21)*N('Peta CPL'!$F$21)),"")) | W7: =IF(OR($B7="",'Peta CPL'!$A$8=""),"",IFERROR((N(L7)*N('Peta CPL'!$C$14)*N('Peta CPL'!$G$14)+N(M7)*N('Peta CPL'!$C$15)*N('Peta CPL'!$G$15)+N(N7)*N('Peta CPL'!$C$16)*N('Peta CPL'!$G$16)+N(O7)*N('Peta CPL'!$C$17)*N('Peta CPL'!$G$17)+N(P7)*N('Peta CPL'!$C$18)*N('Peta CPL'!$G$18)+N(Q7)*N('Peta CPL'!$C$19)*N('Peta CPL'!$G$19)+N(R7)*N('Peta CPL'!$C$20)*N('Peta CPL'!$G$20)+N(S7)*N('Peta CPL'!$C$21)*N('Peta CPL'!$G$21))/(N('Peta CPL'!$C$14)*N('Peta CPL'!$G$14)+N('Peta CPL'!$C$15)*N('Peta CPL'!$G$15)+N('Peta CPL'!$C$16)*N('Peta CPL'!$G$16)+N('Peta CPL'!$C$17)*N('Peta CPL'!$G$17)+N('Peta CPL'!$C$18)*N('Peta CPL'!$G$18)+N('Peta CPL'!$C$19)*N('Peta CPL'!$G$19)+N('Peta CPL'!$C$20)*N('Peta CPL'!$G$20)+N('Peta CPL'!$C$21)*N('Peta CPL'!$G$21)),"")) | X7: =IF(OR($B7="",'Peta CPL'!$A$9=""),"",IFERROR((N(L7)*N('Peta CPL'!$C$14)*N('Peta CPL'!$H$14)+N(M7)*N('Peta CPL'!$C$15)*N('Peta CPL'!$H$15)+N(N7)*N('Peta CPL'!$C$16)*N('Peta CPL'!$H$16)+N(O7)*N('Peta CPL'!$C$17)*N('Peta CPL'!$H$17)+N(P7)*N('Peta CPL'!$C$18)*N('Peta CPL'!$H$18)+N(Q7)*N('Peta CPL'!$C$19)*N('Peta CPL'!$H$19)+N(R7)*N('Peta CPL'!$C$20)*N('Peta CPL'!$H$20)+N(S7)*N('Peta CPL'!$C$21)*N('Peta CPL'!$H$21))/(N('Peta CPL'!$C$14)*N('Peta CPL'!$H$14)+N('Peta CPL'!$C$15)*N('Peta CPL'!$H$15)+N('Peta CPL'!$C$16)*N('Peta CPL'!$H$16)+N('Peta CPL'!$C$17)*N('Peta CPL'!$H$17)+N('Peta CPL'!$C$18)*N('Peta CPL'!$H$18)+N('Peta CPL'!$C$19)*N('Peta CPL'!$H$19)+N('Peta CPL'!$C$20)*N('Peta CPL'!$H$20)+N('Peta CPL'!$C$21)*N('Peta CPL'!$H$21)),"")) | Y7: =IF(OR($B7="",'Peta CPL'!$A$10=""),"",IFERROR((N(L7)*N('Peta CPL'!$C$14)*N('Peta CPL'!$I$14)+N(M7)*N('Peta CPL'!$C$15)*N('Peta CPL'!$I$15)+N(N7)*N('Peta CPL'!$C$16)*N('Peta CPL'!$I$16)+N(O7)*N('Peta CPL'!$C$17)*N('Peta CPL'!$I$17)+N(P7)*N('Peta CPL'!$C$18)*N('Peta CPL'!$I$18)+N(Q7)*N('Peta CPL'!$C$19)*N('Peta CPL'!$I$19)+N(R7)*N('Peta CPL'!$C$20)*N('Peta CPL'!$I$20)+N(S7)*N('Peta CPL'!$C$21)*N('Peta CPL'!$I$21))/(N('Peta CPL'!$C$14)*N('Peta CPL'!$I$14)+N('Peta CPL'!$C$15)*N('Peta CPL'!$I$15)+N('Peta CPL'!$C$16)*N('Peta CPL'!$I$16)+N('Peta CPL'!$C$17)*N('Peta CPL'!$I$17)+N('Peta CPL'!$C$18)*N('Peta CPL'!$I$18)+N('Peta CPL'!$C$19)*N('Peta CPL'!$I$19)+N('Peta CPL'!$C$20)*N('Peta CPL'!$I$20)+N('Peta CPL'!$C$21)*N('Peta CPL'!$I$21)),"")) | Z7: =IF($B7="","",IFERROR((N(L7)*N('Peta CPL'!$C$14)+N(M7)*N('Peta CPL'!$C$15)+N(N7)*N('Peta CPL'!$C$16)+N(O7)*N('Peta CPL'!$C$17)+N(P7)*N('Peta CPL'!$C$18)+N(Q7)*N('Peta CPL'!$C$19)+N(R7)*N('Peta CPL'!$C$20)+N(S7)*N('Peta CPL'!$C$21))/100,""))
